Workbook

Sheet Sheet1
A1: 笔记ID | B1: 笔记类型 | C1: 笔记标题 | D1: 笔记正文 | E1: 字符数 | F1: 点赞数 | G1: 收藏数 | H1: 评论数 | I1: 分享数 | J1: 总互动 | K1: 作者昵称 | L1: 作者ID | M1: 发布IP | N1: 发布时间 | O1: 作者主页 | P1: 笔记链接 | Q1: 笔记标签 | R1: CTR | S1: 互动率 | T1: 回淘率
A2: 68839c35000000000d0259ce | B2: normal | C2: 六年级娃实测：身高定制书包超实用！ | D2: 果果今年六年级，课本习题已经堆到像小山！为了她小学这最后一年，也为初中做准备，换书包我超认真！研究了一圈，锁定了戈撒驰和贝克曼两款口碑很好的护脊书包，买回来实测后挑到了适合做初中生书包的宝藏书包！实测重点：六年级背得舒服，初中也能继续用·✅ 护脊减负戈撒驰：后背内侧隐藏得有身高刻度，140-180cm身高均可调节，按照果果身高调好之后，背上身就像是量身定制一样，还真是“高”定包，刚好贴合后背！内置的U型铝制支撑杆，符合孩子脊柱曲线，结合背板稳稳支撑起重量，娃腰背自然挺直，正确背负后，减压效果能达64.8%，十斤重的书包背出了三斤的轻感，难怪果果说比平时的书包好背多了贝克曼：固定140-175cm，内置S型护脊铝条，有支撑力，减压效果是40%·✅容量戈撒驰：扩容+分层设计，六年级30L完全够用，到初中扩容拉链一打开秒变35L。主袋能装书本+作业+练习册，多功能收纳仓放钥匙、便利贴，一目了然，他们家大容量的笔盒也很适合文具多的学生。还有个前袋放衣服、运动装备，小升初过渡无压力~贝克曼：35L大容量，对小学来说有点大，初中是够用的，分层比较简单，收纳的时候需要孩子自己合理规划·✅细节戈撒驰背垫是3D眼蜂窝网面+中空凹槽，跑跳10分钟，后背都没有闷汗；而且侧兜较深，放水杯很稳当。贝克曼透气也不错，侧兜比较适合放大一些的水杯。对比下来，我们选了戈撒驰，娃背得舒服，妈也更省心。·建议：如果孩子六年级，提前选一款能过渡到初中的护脊书包真的很重要，省钱又省心！戈撒驰这款从设计到容量都很合适，推荐给同样操心的宝妈们~#Gotyasatch护脊书包[话题]# #戈撒驰护脊书包[话题]# #gotyasatch书包[话题]# #戈撒驰书包[话题]# #德国戈撒驰书包[话题]# #小学生书包[话题]# #戈撒驰身高定制书包[话题]# #护脊书包[话题]# #大容量书包[话题]# #护脊书包分享[话题]# #初中生书包[话题]# #高颜值书包[话题]# #书包分享[话题]# #戈撒驰高定护脊书包[话题]# | E2: =LEN(D2) -> 854 | F2: 106 | G2: 83 | H2: 50 | I2: 7 | J2: 246 | K2: 果然妈妈吖 | L2: 637f9436000000001f017452 | M2: 河北 | N2: 2025-07-26 03:44:26 | O2: https://www.xiaohongshu.com/user/profile/637f9436000000001f017452?&xsec_source=pc_note | P2: https://www.xiaohongshu.com/discovery/item/68839c35000000000d0259ce?app_platform=android&ignoreEngage=true&app_version=8.47.0&share_from_user_hidden=true&xsec_source=app_share&type=normal&xsec_token=CBuSUtunJk9YTYeP1cz6p25i62wQ2aE3YBzH7NiROMToc=&author_share=1 | Q2: Gotyasatch护脊书包,戈撒驰护脊书包,gotyasatch书包,戈撒驰书包,德国戈撒驰书包,小学生书包,戈撒驰身高定制书包,护脊书包,大容量书包,护脊书包分享,初中生书包,高颜值书包,书包分享,戈撒驰高定护脊书包 | R2: =VLOOKUP(A2,[1]蒲公英数据!A:H,8,0) -> 0.079919001 | S2: =VLOOKUP(A2,[1]蒲公英数据!A:I,9,0) -> 0.15033784 | T2: =VLOOKUP(A2,[1]蒲公英数据!A:J,10,0) -> 0.5265902
A3: 68886af7000000002301bf48 | B3: normal | C3: 疯了吧❗是谁给小学生安排这个书包的啊❓ | D3: 过完暑假娃就上五年级了，课业猛增，书包越来越重，已经直接关系到孩子的脊柱健康和学习心情了，为了让他背包不弯腰，同时也把升学准备提上日程，作为过来人（老大已上岸），我直接给娃换了一个护脊书包，今天来聊聊选购心得+升学小攻略~√身高定制。给小学生安排这款护脊书包的首要原因是它可根据孩子的身高定制调节，货真价实的“高”定包，从1米4到1米8都可以用，小升初都不用换书包，直接当初中生书包！√护脊减负。我家老大以前就是没注意，每天上下学背着 “乌龟壳”，现在都有点驼背。本身男孩就不怎么注意这方面，真等长大了就更难纠正了，所以安排护脊书包很有必要。戈撒驰内置的U型铝制支撑杆，模拟人体脊柱曲线的设计，能更好贴合孩子后背，结合背板形成稳定的支撑力，有效保护脊柱。调好身高刻度，扣好胸扣、腰扣、肩扣后同样的书本背起来轻松多了，减负效果从孩子挺拔的身躯就能看出来~√大容量+小细节。扩容设计很贴心，娃小学30L的容量妥妥够用，到了初中课业更多，到时候扩容拉链一拉开，又多了5L可以用。主隔层轻松装下语数英课本+各种练习册，侧兜放水杯、雨伞，配套的笔盒收纳各种笔、尺子，还有个前袋能塞下一些体育用具，所有物品都能放得井井有条！书包不是那种很软的材质，看起来是板正有型的，而且还防水，太适合这个年龄段的小男孩了。升学指南五年级就要开始关注目标初中（公立对口/民办摇号/特色班等）的招生政策了！信息差很关键，多和老师沟通，关注官方发布。其次家长自己先稳住！避免过度焦虑传递给孩子。多鼓励，少比较，帮助孩子建立自信，积极面对挑战。选对护脊书包是孩子健康学习的基础，升学准备需要智慧、耐心和科学的规划。希望这份来自“过来人”的指南能帮到你！#Gotyasatch护脊书包[话题]# #戈撒驰护脊书包[话题]# #gotyasatch书包[话题]# #戈撒驰书包[话题]# #德国戈撒驰书包[话题]# #戈撒驰身高定制书包[话题]# #小学生书包[话题]# #大容量书包[话题]# #初中生书包[话题]# #戈撒驰高定护脊书包[话题]# | E3: =LEN(D3) -> 859 | F3: 87 | G3: 40 | H3: 23 | I3: 6 | J3: 156 | K3: 慧慧 | L3: 5981238382ec3924b5fd6827 | M3: 浙江 | N3: 2025-07-29 07:04:12 | O3: https://www.xiaohongshu.com/user/profile/5981238382ec3924b5fd6827?&xsec_source=pc_note | P3: https://www.xiaohongshu.com/discovery/item/68886af7000000002301bf48?app_platform=android&ignoreEngage=true&app_version=8.47.0&share_from_user_hidden=true&xsec_source=app_share&type=normal&xsec_token=CBtaPkwJ0ri0aNzuGoBEzszOZKftBY7y59CALcBYFM8AQ=&author_share=1 | Q3: Gotyasatch护脊书包,戈撒驰护脊书包,gotyasatch书包,戈撒驰书包,德国戈撒驰书包,戈撒驰身高定制书包,小学生书包,大容量书包,初中生书包,戈撒驰高定护脊书包 | R3: =VLOOKUP(A3,[1]蒲公英数据!A:H,8,0) -> 0.10548881 | S3: =VLOOKUP(A3,[1]蒲公英数据!A:I,9,0) -> 0.035730237 | T3: =VLOOKUP(A3,[1]蒲公英数据!A:J,10,0) -> 0.50932611
A4: 689c2c3f000000001b01f510 | B4: normal | C4: 护脊书包测评：拯救娃的驼背危机！ | D4: ✨四升五课本和作业量巨增，娃背旧书包回到家总会揉肩膀，小背影肉眼可见的微驼…升学拼的不只是分数，更是好身体。老母亲研究了两大顶流护脊书包——戈撒驰vsGMT，来看看哪款更适合我家娃！⬇️--✨开箱第一眼！颜值控暴击，戈撒驰暗黑机能风+荧光绿线条的配色，哑光耐磨面料，符合我家娃不羁随性的个性。GMT是学院风，方正规整，乖乖学生可以pick！--✨【理性四维对比】1️⃣成长兼容性戈撒驰：身高定制书包，后背暗藏身高刻度尺，140-180cm自由调，对我们刚好一米四的娃很友好。按身高调好后完美贴合后背，跑跳追闹稳当不晃悠。GMT，固定档位150-180cm。2️⃣护脊减负戈撒驰：U型铝制支撑杆+3D背板，背上的一刹那，小腰板就挺直了，很神奇！不会拉扯身体。肩带+腰带+胸带，把重量分散到腰背，官方实测减负效果达64.8%！我按照自己的身高调到160cm试背，感觉也很轻松，负重感不明显。而且在现在三十多度的高温天气下，背着不会觉得闷，透气性不错。GMT：S型护脊铝条+背板，支撑还不错。3️⃣容量收纳戈撒驰：分区多！主隔层装书本、练习册、各科作业，多功能仓塞剪刀、胶水和执勤卡等小物件。弹力前袋连娃的足球都塞得进，侧兜放大水杯，东西各归其位！戳我的还有它30L+5L扩容的设计，小学30L够用，等小升初当初中生书包用时，扩容拉链打开能多5L，很实用！PS：戈撒驰家的笔袋也很能装，几十支笔轻松装下GMT：30L容量，有两个大隔层，前面小拉链袋放文具，侧兜放纸巾和水杯，日常也够用。4️⃣设计细节戈撒驰：反光条有好几处，面积大。夜间实测，反光条亮度高，很安全。侧边袋带锁扣，要正儿八经去拉才能拉开，防盗性max。GMT：有反光条设计。结论戈撒驰身高定制这个点真的无法拒绝，从四年级背到初中没问题，妥妥的长期投资，而且减负效果明显，细节设计实用又安全，颜值还踩在我们的审美上，闭眼入了！#Gotyasatch护脊书包[话题]##戈撒驰护脊书包[话题]##gotyasatch书包[话题]##戈撒驰书包[话题]##德国戈撒驰书包[话题]##护脊书包[话题]##大容量书包[话题]##初中生书包[话题]##戈撒驰高定护脊书包[话题]##戈撒驰身高定制书包[话题]# | E4: =LEN(D4) -> 928 | F4: 28 | G4: 14 | H4: 35 | I4: 10 | J4: 87 | K4: GABY WOW | L4: 5540cda5af8147407f13b4c6 | M4: 上海 | N4: 2025-08-13 10:50:37 | O4: https://www.xiaohongshu.com/user/profile/5540cda5af8147407f13b4c6?&xsec_source=pc_note | P4: https://www.xiaohongshu.com/discovery/item/689c2c3f000000001b01f510?app_platform=android&ignoreEngage=true&app_version=8.47.0&share_from_user_hidden=true&xsec_source=app_share&type=normal&xsec_token=CBJ7yT-hrOCpZjOJSoNJYPlkKZkfIGCoK_w4OFFp3rmog=&author_share=1 | Q4: Gotyasatch护脊书包,戈撒驰护脊书包,gotyasatch书包,戈撒驰书包,德国戈撒驰书包,护脊书包,大容量书包,初中生书包,戈撒驰高定护脊书包,戈撒驰身高定制书包 | R4: =VLOOKUP(A4,[1]蒲公英数据!A:H,8,0) -> 0.062860553 | S4: =VLOOKUP(A4,[1]蒲公英数据!A:I,9,0) -> 0.092827004 | T4: =VLOOKUP(A4,[1]蒲公英数据!A:J,10,0) -> 0.45738295
A5: 689c56af000000001d01d09f | B5: normal | C5: 魔都妈妈 | 踩雷后才懂护脊书包的好‼️ | D5: 五年级的小姑娘正是长身体的时候体态这事儿真得上心❤就说我家吐司吧，去年检查出骨盆前倾站着总爱挺肚子还伴有高低肩估计和练小提琴有关.当了妈才知道孩子长身体的时候脊椎健康、体态问题真是一点都马虎不得连每天背着的书包，都得好好挑挑才行.妈妈们听说过可以身高定制的书包吗？我第一次看到的时候也是很惊讶戈撒驰护脊书包——孩子专属的“高”定包✅身高在140-180cm区间内可以，根据孩子实际身高灵活调节，上了初中也能当初中生书包用，不用担心书包不合身，护脊效果大打折扣‼️吐司背上就跟我说，这书包跟以前的真不一样↓.⭕【护脊减负，孩子轻松】以前的书包后背软趴趴的，重量全压在肩膀和腰上长时间乘坐地铁或走路，到家后肩膀很吃力而戈撒驰护脊书包采用U型铝制支架杆+3D背板贴在背上像第二层皮肤，能稳稳顶住书包重量和外力撞击按身高调好书包，扣好肩带、胸扣和腰扣减负效果能达64.8%难怪吐司说背着轻松多了，不用刻意叮嘱也能挺直背.⭕【容量大，合理收纳】现在不管是小学生书包还是初中生书包除了装书外，还要带各种社团活动装备吐司要带琴谱、京剧鞋、京剧服和科创社团的小工具如果书包不够大，每次都是大包小包进校门[汗颜R].这款书包是35L扩容设计分层很科学：2个主隔层+多功能收纳袋+创意前袋可以装防晒衣、球鞋、画笔等额外的生活用品很适合住宿、兴趣班和户外运动多的孩子我周围体制外学校的孩子就特别喜欢这种因为他们课后社团多，装备对容量需求也大！.陪孩子一起长高的成长型书包从结构、支撑、收纳都为孩子“减轻负担”细节上也很用心❤反光条设计让孩子夜行更安全小高和初中生家长，不心动吗？.新学期，选对一个好书包不仅是给孩子新装备，更是给她成长的新动力带着新目标，一起加油吧！#Gotyasatch护脊书包[话题]# #戈撒驰护脊书包[话题]##gotyasatch书包[话题]##戈撒驰书包[话题]# #德国戈撒驰书包[话题]# #护脊书包[话题]# #大容量书包[话题]# #初中生书包[话题]# #戈撒驰高定护脊书包[话题]# #戈撒驰身高定制书包[话题]# @日常薯 @生活薯 @小红书创作助手 @薯条小助手 | E5: =LEN(D5) -> 892 | F5: 16 | G5: 13 | H5: 11 | I5: 3 | J5: 43 | K5: 小吐司妈妈 | L5: 5acefe494eacab46d1997abe | M5: 上海 | N5: 2025-08-14 03:35:09 | O5: https://www.xiaohongshu.com/user/profile/5acefe494eacab46d1997abe?&xsec_source=pc_note | P5: https://www.xiaohongshu.com/discovery/item/689c56af000000001d01d09f?app_platform=android&ignoreEngage=true&app_version=8.47.0&share_from_user_hidden=true&xsec_source=app_share&type=normal&xsec_token=CBJ7yT-hrOCpZjOJSoNJYPln37Qrxzf0CXk-YVJ775zfI=&author_share=1 | Q5: Gotyasatch护脊书包,戈撒驰护脊书包,gotyasatch书包,戈撒驰书包,德国戈撒驰书包,护脊书包,大容量书包,初中生书包,戈撒驰高定护脊书包,戈撒驰身高定制书包 | R5: =VLOOKUP(A5,[1]蒲公英数据!A:H,8,0) -> 0.061035327 | S5: =VLOOKUP(A5,[1]蒲公英数据!A:I,9,0) -> 0.042979943 | T5: =VLOOKUP(A5,[1]蒲公英数据!A:J,10,0) -> 0.42546584
A6: 688879160000000023031045 | B6: normal | C6: 护脊书包实测！开学季选购看准减负+调节 | D6: 孩子马上就要小升初了, 最近总念叨书包太沉，想着干脆给她换个初中也能背的护脊书包，最好能多背几年！挑来挑去，锁定了两个口碑款：德国戈撒驰和BKM今天就来对比看看哪款更合适！✅藏在细节里的“成长友好度”戈撒驰有独研身高定制：后背内侧藏的身高刻度！140-180cm身高都能调，乔乔现在155cm，轻轻移动就到位了，等升入初中后，作为初中生书包时也只需要根据乔乔最新身高调节好刻度就能继续用，适合长远打算~✅轻≠省力，护脊减负效果更重要有些超轻书包没支撑，装多了就往下坠，反而压肩膀。这俩都有支撑，戈撒驰内置的是U型铝制支撑杆，BKM是护脊铝条，装同样重的东西上身后乔乔说都比旧书包轻，查了才知道，它们通过多点受力设计分散重量，实现科学减负，戈撒驰经专业测试能减负64.8%，10斤书背出3斤多的轻感！BKM是40%，效果也挺好～✅贴不贴合, 一背就知道戈撒驰：像“长在背上”一样稳。肩带是加宽加厚的，不硌肩膀；透气背垫摸起来软乎乎的有弹性，贴合感很好，跑跳时书包都不晃，娃弯腰系鞋带时，书包也不会往前坠。BKM：缓冲软垫很舒服，加上透气的设计，也比旧书包好多了。✅容量收纳：都是35L大容量，但用法不一样戈撒驰：30L大容量，装下15本课本+保温杯+跳绳+配套大笔袋，前袋能塞备用校服，分区清晰到娃自己都能收拾，让老母亲省事不少～等以后升入初中后做初中生书包时，拉开扩容拉链，马上又能多装5LBKM：分区也很细，三层大口袋放日常书本作业，外挂包可以放钥匙。 材质上两款都是环保面料，抗造防水。我们最后留下了戈撒驰，选护脊书包别只看“当下舒服”，能陪孩子从小学用到高中的，才是真划算～选对了就是对孩子未来的有效投资，希望这份详细攻略能帮到同样纠结的你！#Gotyasatch护脊书包[话题]# #戈撒驰护脊书包[话题]# #gotyasatch书包[话题]# #戈撒驰书包[话题]# #德国戈撒驰书包[话题]# #小学生书包[话题]# #护脊书包[话题]# #大容量书包[话题]# #护脊书包分享[话题]# #初中生书包[话题]# #戈撒驰身高定制书包[话题]##高颜值书包[话题]# #书包分享[话题]# #戈撒驰高定护脊书包[话题]# | E6: =LEN(D6) -> 917 | F6: 218 | G6: 76 | H6: 25 | I6: 14 | J6: 333 | K6: 乔乔Joela_mom | L6: 5db2cb310000000001004eda | M6: 广东 | N6: 2025-07-29 08:49:51 | O6: https://www.xiaohongshu.com/user/profile/5db2cb310000000001004eda?&xsec_source=pc_note | P6: https://www.xiaohongshu.com/discovery/item/688879160000000023031045?app_platform=android&ignoreEngage=true&app_version=8.47.0&share_from_user_hidden=true&xsec_source=app_share&type=normal&xsec_token=CBtaPkwJ0ri0aNzuGoBEzszJASWLmY9XrhZ88K0oCnT6Y=&author_share=1 | Q6: Gotyasatch护脊书包,戈撒驰护脊书包,gotyasatch书包,戈撒驰书包,德国戈撒驰书包,小学生书包,护脊书包,大容量书包,护脊书包分享,初中生书包,戈撒驰身高定制书包,高颜值书包,书包分享,戈撒驰高定护脊书包 | R6: =VLOOKUP(A6,[1]蒲公英数据!A:H,8,0) -> 0.10204305 | S6: =VLOOKUP(A6,[1]蒲公英数据!A:I,9,0) -> 0.033921435 | T6: =VLOOKUP(A6,[1]蒲公英数据!A:J,10,0) -> 0.4209208
A7: 6888634d000000002501ab4b | B7: normal | C7: 连夜下单护脊书包，承包孩子的小初高！ | D7: 姐姐小升初时，书包天天都是快撑爆的状态，小小的身板承受千斤重。但一想快毕业了，就准备初中再换书包，可没想到不合身的书包严重影响了她的体态，现在纠正起来太困难了！今年弟弟马上五年级，本身男孩的体态习惯就比女孩差，再加上姐姐的经历，我赶紧趁暑假给他挑了一款减负的护脊书包——德国戈撒驰护脊书包，用过之后不得不说，这次买对了！.一个实用又特别的独研细节设计：它能根据身高精准调节，适配140-180cm的孩子，妥妥的“高”定包！弟弟155cm，调到对应刻度，就像专门为他定制的一样，背上贴得紧紧的，初中生书包也直接内定它了.护脊也不是智商税，内置的U型铝制支撑杆，是专业级登山包同款设计，模拟人体脊柱曲线，结合3D背板，给孩子稳稳的支撑力，再也不用担心书包负重挤压脊柱，而且加上可卸力的胸扣、腰扣、肩扣，十斤的书包背起来像只有三斤多，弟弟背上之后说轻多了，跑跳都不会“打”他的背，减负效果实打实地能看见。.人性化的容量分区！30+5L的扩容设计，无论小学高年级还是初中都能满足。两个主隔层放书本、作业、饭盒还有他们家配套大容量笔盒，侧边放水杯、雨伞，另一边是带拉链的，放零钱、钥匙不担心丢。弟弟很喜欢它的前袋，拉开放衣服、足球完全没问题，直接解放双手。颜值也深得他心，经典配色，大方又亮眼，材质深得老母亲的心，它采用的环保面料不仅契合可持续发展的理念，而且质感超好，抗造扎实，耐磨耐用还防水，包身设计得有反光条，走夜路也很安全。.换了护脊书包之后，感觉他都更爱学习了哈哈，无论是背上书包走路还是坐在课桌前学习，体态都可好了，这波入手不亏！#Gotyasatch护脊书包[话题]# #戈撒驰护脊书包[话题]# #gotyasatch书包[话题]# #戈撒驰书包[话题]# #德国戈撒驰书包[话题]# #小学生书包[话题]# #护脊书包[话题]# #大容量书包[话题]# #护脊书包分享[话题]# #初中生书包[话题]# #高颜值书包[话题]# #书包分享[话题]# #戈撒驰高定护脊书包[话题]# #戈撒驰身高定制书包[话题]# | E7: =LEN(D7) -> 860 | F7: 173 | G7: 83 | H7: 36 | I7: 1 | J7: 293 | K7: 琥珀 | L7: 586b5cf75e87e7383463a1a0 | M7: 河南 | N7: 2025-07-29 09:16:53 | O7: https://www.xiaohongshu.com/user/profile/586b5cf75e87e7383463a1a0?&xsec_source=pc_note | P7: https://www.xiaohongshu.com/discovery/item/6888634d000000002501ab4b?app_platform=android&ignoreEngage=true&app_version=8.47.0&share_from_user_hidden=true&xsec_source=app_share&type=normal&xsec_token=CBtaPkwJ0ri0aNzuGoBEzszOe5cqiENKl42PiD-DSlUGg=&author_share=1 | Q7: Gotyasatch护脊书包,戈撒驰护脊书包,gotyasatch书包,戈撒驰书包,德国戈撒驰书包,小学生书包,护脊书包,大容量书包,护脊书包分享,初中生书包,高颜值书包,书包分享,戈撒驰高定护脊书包,戈撒驰身高定制书包 | R7: =VLOOKUP(A7,[1]蒲公英数据!A:H,8,0) -> 0.078122395 | S7: =VLOOKUP(A7,[1]蒲公英数据!A:I,9,0) -> 0.087157595 | T7: =VLOOKUP(A7,[1]蒲公英数据!A:J,10,0) -> 0.41202282
A8: 687f4f8d0000000010024eca | B8: normal | C8: 护脊书包怎么选？有效护脊＞品牌＞颜值 | D8: ‼️超500万青少年受脊柱侧弯困扰‼️约80%的青少年存在形体不良的问题之前我家娃在学校做【脊柱侧弯筛查】，结果是4度，介于正常和低风险之间问了在骨科上班的同学，他跟我说：孩子每天背着很重的书包，脖子会代偿发力，久而久之就容易引起脊柱问题看着孩子背着沉甸甸的书包，走路不自觉地弓着背，是时候把健康护脊提上日程了！‍⚕提早预防的关键，就是减轻脊柱受压！✅为什么要给孩子用护脊书包？✅护脊书包怎么选？京妈总结在图2、图3里了，家长们真的要认真看看❤综合对比好多款，我给孩子选了戈撒驰护脊书包！这可是能跟着孩子“长”个的身高定制书包，背后隐藏刻度尺，孩子身高在140-180cm随意调，所以我也叫它“高”定包。以前的书包背不了多久就会卡肩膀，需要更换，现在刻度一调，背起来服服帖帖，从小学用到初中都没问题~‍♀很多人选护脊书包有个误区，认为【轻就是护脊】但其实书包自重轻不代表背着轻❌，护脊效果好不好，关键看护脊设计是否科学！✅戈撒驰在这方面就做得很好，内置U型铝制支撑杆搭配立体高弹背板，时刻给足支撑力。再加上四点承托设计，让肩部、胸部、腰部形成多点受力，把肩部重量分散到腰背部，十斤的书包背出三斤轻感，专业数据显示减负能达64.8%！娃背上后，身姿都挺拔了不少✅35L扩容大容量+分层设计，收纳变得很简单。课本、试卷、水杯、雨伞轻轻松松装下，甚至课外活动要用的足球、乒乓球拍都能塞进前袋！我还给儿子准备了同款大容量笔袋，再也不用担心孩子笔、尺子随便乱丢了。晚上放学从路灯下经过，书包上的反光条亮闪闪的，远远就能看见，安全感拉满！‍♀️护脊这事真等不得，早一天行动，少一分隐患要是你也在给娃挑护脊书包，不妨看看戈撒驰❤️能跟着孩子“长大”的书包，非常省心！#Gotyasatch护脊书包[话题]##戈撒驰护脊书包[话题]##gotyasatch书包[话题]##戈撒驰书包[话题]##德国戈撒驰书包[话题]##小学生书包[话题]##护脊书包[话题]##大容量书包[话题]##护脊书包分享[话题]##初中生书包[话题]##高颜值书包[话题]##书包分享[话题]##戈撒驰高定护脊书包[话题]##戈撒驰身高定制书包[话题]# | E8: =LEN(D8) -> 907 | F8: 221 | G8: 63 | H8: 10 | I8: 8 | J8: 302 | K8: 京妈说 | L8: 556cd2ede58d131daeb485e9 | M8: 天津 | N8: 2025-07-22 09:33:46 | O8: https://www.xiaohongshu.com/user/profile/556cd2ede58d131daeb485e9?&xsec_source=pc_note | P8: https://www.xiaohongshu.com/discovery/item/687f4f8d0000000010024eca?app_platform=android&ignoreEngage=true&app_version=8.47.0&share_from_user_hidden=true&xsec_source=app_share&type=normal&xsec_token=CBcmwSdrBEFQSlPQtE-mrJX55_e3Dji6Ya2XEYfgR4xR8=&author_share=1 | Q8: Gotyasatch护脊书包,戈撒驰护脊书包,gotyasatch书包,戈撒驰书包,德国戈撒驰书包,小学生书包,护脊书包,大容量书包,护脊书包分享,初中生书包,高颜值书包,书包分享,戈撒驰高定护脊书包,戈撒驰身高定制书包 | R8: =VLOOKUP(A8,[1]蒲公英数据!A:H,8,0) -> 0.10883057 | S8: =VLOOKUP(A8,[1]蒲公英数据!A:I,9,0) -> 0.070535268 | T8: =VLOOKUP(A8,[1]蒲公英数据!A:J,10,0) -> 0.39950166
A9: 6895ef150000000003031c2d | B9: normal | C9: 再不抓体态就晚了！国际学校初中生书包实测 | D9: 自从小孩哥进入初中，青春期变化实在太快了！个头猛窜不说，整个气质都大变样，短短一年，从拉小提琴的文艺娃转型为摇滚style的电吉他手国际学校开学早，还有两周时间，小孩哥就升八年级了！除了新开选课，还有更多社团活动，他摩拳擦掌要参加——这意味着每天要背更多的东西去上学书本、电脑、体育服、球鞋、乐器、谱夹……书包升级刻不容缓，老母亲赶紧研究一波～护脊书包有利于孩子的脊柱健康，而且这么多年观察下来，身边国际学校娃，最常见背的就是戈撒驰和贝克曼，咱就对比测评一下它俩吧1️⃣身高定制戈撒驰：从140-180cm随意调节，根据身高进行定制，属于是学生中的“高”定包了，操作简单，小孩哥自己就能调。调好后，书包与孩子后背贴合更佳，持续呵护脊柱健康。贝克曼：固定140-175cm可用2️⃣护脊减负戈撒驰：U型铝制支撑杆自然贴合脊柱曲线，还能吸收书包的撞击力保护脊柱；结合背垫、肩带、胸带和腰带，把身体包裹后，相当于增加了受力面积，背着自然就轻了，减负效果能达64.8%贝克曼：仿生S型铝支架，支撑不错，减负效果能达40%3️⃣收纳系统戈撒驰：30L，分层科学，主副隔层装笔记本电脑、课本、体育服、配套的大容量笔袋，多功能仓放计算器和小物件；哥哥还开发了创意外挂，收纳球鞋袋，直接解放双手了贝克曼：30L，两隔层+前兜，侧兜适合放大水杯4️⃣款式颜色小孩哥现在什么都要追求酷，他喜欢戈撒驰经典系列的渐变薄荷色，灰色+浅绿，书包正面再配个其他颜色的个性标记带，又酷又艺术，不愧是我亲自生出来的娃对比下来，本次初中生书包升级，我们最终选择戈撒驰护脊书包！小孩哥已经迫不及待想返校了，每天都念叨好想回学校～其实小孩哥还有一项秘密计划，下个月再公布啦～#国际学校[话题]# #国际学校初中生[话题]# #Gotyasatch护脊书包[话题]# #戈撒驰护脊书包[话题]# #gotyasatch书包[话题]# #戈撒驰书包[话题]# #德国戈撒驰书包[话题]# #小学生书包[话题]# #护脊书包[话题]# #大容量书包[话题]# #护脊书包分享[话题]# #初中生书包[话题]# #高颜值书包[话题]# #书包分享[话题]# #戈撒驰高定护脊书包[话题]# #戈撒驰身高定制书包[话题]# #书包测评[话题]# | E9: =LEN(D9) -> 947 | F9: 46 | G9: 32 | H9: s | I9: 14 | J9: 108 | K9: 匪头小白 | L9: 584a272882ec395eee0b91e4 | M9: 北京 | N9: 2025-08-09 09:11:43 | O9: https://www.xiaohongshu.com/user/profile/584a272882ec395eee0b91e4?&xsec_source=pc_note | P9: https://www.xiaohongshu.com/discovery/item/6895ef150000000003031c2d?app_platform=android&ignoreEngage=true&app_version=8.47.0&share_from_user_hidden=true&xsec_source=app_share&type=normal&xsec_token=CBnjRxmTkdR3m3KskfN9ZuNcicUbxdVRRkg1sRcqpzMZo=&author_share=1 | Q9: 国际学校,国际学校初中生,Gotyasatch护脊书包,戈撒驰护脊书包,gotyasatch书包,戈撒驰书包,德国戈撒驰书包,小学生书包,护脊书包,大容量书包,护脊书包分享,初中生书包,高颜值书包,书包分享,戈撒驰高定护脊书包,戈撒驰身高定制书包,书包测评 | R9: =VLOOKUP(A9,[1]蒲公英数据!A:H,8,0) -> 0.083779111 | S9: =VLOOKUP(A9,[1]蒲公英数据!A:I,9,0) -> 0.013474144 | T9: =VLOOKUP(A9,[1]蒲公英数据!A:J,10,0) -> 0.39259758
A10: 6860dc540000000023005fbd | B10: normal | C10: 跨国转学能适应吗？国际初中生书包怎么选？ | D10: ✈️我家因为爸爸工作调动，全家一起回杭州了。哥哥目前在杭州国际学校读8年级，跨国转学一学期下来，适应没啥问题，给大家分享下美国初中和国内国际学校课程上的差别美初：5门主课 英、数、科、历史、体育+3门选修的副课国际学校：8门主课：英、数、语、物、化、生、史、地6门副课：道法、体育、戏剧、美术、电脑、劳技2门兴趣课这边数学分中教课+外教课，学得更多更细，难度也比美国更难。英语是纯外教两边差不多，定期有整本书阅读，每周有测试。平时电脑上的作业有IXL和MYON。像语文和一些副课、兴趣课都是美国没有的。而且很多课程都是分层教学，课间就是背起重重的书包在不同课堂间穿梭，一个个小身躯被压得弯腰驼背。为了保护脊柱，也为升高中做准备，我给他换了个更合适的初中生书包——德国品牌戈撒驰护脊书包。我选它的几大理由1️⃣后背内侧隐藏了身高刻度，可根据孩子身高定制，据我所知其它护脊书包可做不到！可以说是“高”定包咯，140-180cm可调，孩子现在是发育期，身高猛涨，选择可调节的书包能确保时刻贴合身体曲线。2️⃣内置U型铝制支撑杆，符合人体工学设计，更贴合孩子背部曲线，能有效防止书包内部的压力挤压脊柱也不会驼背。结合背板构成双层结构，正确背负后，整个书包的重量被分散到腰部、背部，多点受力，不再单一让肩膀承重，轻松许多！胸带+腰带固定后，跑动起来更稳固，孩子课间走班也不担心书包撞击脊柱了3️⃣30L大容量，多隔层设计，主隔层还带电脑收纳位，装作业、书本、饭盒都没问题，他们家配套笔袋我也买了，中性笔、铅笔、橡皮等学习用具都可以放进去，水杯、雨伞放侧边，拿取方便。4️⃣这个能根据身高定制的护脊书包立体挺阔的外形搭配流畅线条，金属锁扣+皮质拉链头细节满满，整体高级又有质感，进校就成为“明星包”，而且面料扎实防水，实用性并存~♥️孩子抓学习，家长就要抓健康，选护脊又实用的初中生书包，真心靠谱！#Gotyasatch护脊书包[话题]# #戈撒驰护脊书包[话题]# #gotyasatch书包[话题]# #戈撒驰书包[话题]# #德国戈撒驰书包[话题]# #小学生书包[话题]# #护脊书包[话题]# #大容量书包[话题]# #护脊书包分享[话题]# #初中生书包[话题]# #大容量书包[话题]# #高颜值书包[话题]# #书包分享[话题]# | E10: =LEN(D10) -> 967 | F10: 107 | G10: 75 | H10: 12 | I10: 15 | J10: 209 | K10: 杭州夫妻美国陪读日记 | L10: 62dcc8b8000000001f017240 | M10: 浙江 | N10: 2025-06-29 12:49:37 | O10: https://www.xiaohongshu.com/user/profile/62dcc8b8000000001f017240?&xsec_source=pc_note | P10: https://www.xiaohongshu.com/discovery/item/6860dc540000000023005fbd?app_platform=android&ignoreEngage=true&app_version=8.47.0&share_from_user_hidden=true&xsec_source=app_share&type=normal&xsec_token=CBmOjP91oxG2VSIOpAFjHVVSNhmJGDxjJrLVaoktwOjQQ=&author_share=1 | Q10: Gotyasatch护脊书包,戈撒驰护脊书包,gotyasatch书包,戈撒驰书包,德国戈撒驰书包,小学生书包,护脊书包,大容量书包,护脊书包分享,初中生书包,高颜值书包,书包分享 | R10: =VLOOKUP(A10,[1]蒲公英数据!A:H,8,0) -> 0.073841643 | S10: =VLOOKUP(A10,[1]蒲公英数据!A:I,9,0) -> 0.027637213 | T10: =VLOOKUP(A10,[1]蒲公英数据!A:J,10,0) -> 0.38419395
A11: 68609b770000000024009804 | B11: normal | C11: 考试周的初中生书包✅沉到背不动？ | D11: ▷[派对R]考试周就这么水灵灵地来了~周末大部分时间都泡在图书馆自习，需要的东西 zui 好一次带齐。▷新入的初中生书包已经成为我们的移动学习城堡了。要是以前的书包，这一堆东西塞不下不说，每次七七回来都是弯腰驼背的，脊柱负重严重超标，长期这样肯定受不了，赶紧给她换了这款德国品牌戈撒驰的护脊书包，护脊+减负黑科技拉满，书包背不动？不存在！[偷笑R]▷专业登山包才用的U型铝制支撑杆，它给娃安排上了，像这种模拟人体脊柱自然曲线的设计，更贴合孩子的背部曲线，里面装得再多，背上去人也是挺拔的，孩子不会因为书装的多就弯腰驼背。而且就算是长期都装得很重，书包背部结构也不容易变形▷身高定制书包不知道大家听说过没？简称“高”定包，可以根据娃的⾝高在140cm-180cm之间的尺寸任意调节，这意味着随着娃长高书包也会“长高”，U型铝制支撑杆一直正确贴合孩子脊柱，不会被长高所影响，这个设计很符合我对德国人务实专业的“刻板印象”了[偷笑R][偷笑R]▷只需要根据身高调节到对应的刻度，背上书包扣上腰扣、胸扣，收紧两侧的腰扣带和肩带，再收紧上肩扣，原本集中在肩膀的重量一下子分散开，转移到身体多个部位，看起来就像被书包包裹住，实现有效减负，所以10斤重的书包背着像只有3斤！娃怎么能不爱！▷初中生书包还有个重要的点：收纳容量不能输！看我们那么多的资料，就知道它真的太能装了！主隔层里面还有个可以装笔记本电脑的隔层，书本、试卷、笔袋都能放进去，副隔层装作业、文件袋，还有中间的扩容设计，就算是下雨天要塞件长袖校服在书包，也是够够的。两侧的多功能收纳袋可以放钥匙、雨伞，另一边放水杯，一目了然，找东西超快，翻包不会乱糟糟啦！整体采用的还是PET环保面料，我看到这个是有认证的，良心品牌。包身360度反光设计，夜间出行我也能放心了。▷进入考试倒计时了，知识可不能减负，就用护脊书包给身体减减负吧！给所有背着“知识重量”前进的娃们加油啦！祝大家考试都顺利呀！#Gotyasatch护脊书包[话题]# #戈撒驰护脊书包[话题]# #gotyasatch书包[话题]# #戈撒驰书包[话题]# #德国戈撒驰书包[话题]# #小学生书包[话题]# #护脊书包[话题]# #大容量书包[话题]# #护脊书包分享[话题]# #初中生书包[话题]# #大容量书包[话题]# #高颜值书包[话题]# #书包分享[话题]# | E11: =LEN(D11) -> 992 | F11: 40 | G11: 12 | H11: 6 | I11: 5 | J11: 63 | K11: 七七妈碎碎念 | L11: 5b28841411be101a389f08f9 | M11: 四川 | N11: 2025-06-29 09:52:54 | O11: https://www.xiaohongshu.com/user/profile/5b28841411be101a389f08f9?&xsec_source=pc_note | P11: https://www.xiaohongshu.com/discovery/item/68609b770000000024009804?app_platform=android&ignoreEngage=true&app_version=8.47.0&share_from_user_hidden=true&xsec_source=app_share&type=normal&xsec_token=CBmOjP91oxG2VSIOpAFjHVVdb8yoJqN9K1TC8atTG78Kg=&author_share=1 | Q11: Gotyasatch护脊书包,戈撒驰护脊书包,gotyasatch书包,戈撒驰书包,德国戈撒驰书包,小学生书包,护脊书包,大容量书包,护脊书包分享,初中生书包,高颜值书包,书包分享 | R11: =VLOOKUP(A11,[1]蒲公英数据!A:H,8,0) -> 0.078529168 | S11: =VLOOKUP(A11,[1]蒲公英数据!A:I,9,0) -> 0.0073504077 | T11: =VLOOKUP(A11,[1]蒲公英数据!A:J,10,0) -> 0.384178
A12: 6860ac060000000010011302 | B12: normal | C12: 护脊书包避坑指南｜选错毁脊椎！ | D12: 谁懂啊！给娃挑书包这事，真是把我折磨得够呛！刚开始没经验，带娃逛商场，娃指着花花绿绿的卡通书包眼睛放光，我一冲动就买了。哪知道这一买竟是踩雷的开始！没用多久孩子就喊肩膀酸、脖子痛，还开始弯腰驼背。检查才发现，长时间背不合适的书包对发育中的脊柱危害极大，那一刻我才意识到自己多疏忽‼️打那以后，我就开启疯狂补课模式，把市面上的书包研究了个透。今天就把 “血泪经验” 总结成避坑指南，分享给各位姐妹！选护脊书包的3个核心点：1️⃣自由调节：精准适配身高普通书包没有身高调节功能，孩子长高以后背着要么肩带过长晃晃悠悠，要么背板不合身加重脊柱负担。这款身高定制书包让我觉得超赞，我现在都叫它“高”定包，因为它后背内侧隐藏着精准的身高刻度，只需轻轻一推，就能在140cm - 180cm的区间内自由调节背幅长度 。对于这个年龄段快速长高的孩子来说，不管什么时候都能拥有贴合身形的背负体验。而且PET环保面料防水又耐磨，一包能用好久，轻松满足孩子多年的成长需求，这下不用烦恼初中生书包怎么选了！2️⃣背负系统：贴合脊柱才是王道普通书包背带窄硬，重量全压在肩膀上，脊柱长时间承受压力，容易变形。戈撒驰护脊书包内置U型铝制支撑杆，搭配上立体背板，能很好地贴合孩子背部曲线。再加上可调节胸扣和腰带，不仅能牢牢固定书包，还能将肩部重量均匀分散到腰背部，实现有效减负，真正做到专业护脊，而不是单纯减薄材料的“伪轻量护脊”。3️⃣分区设计：收纳要科学 没有分区的书包找东西超麻烦，还容易把书本压皱！这个书包35L扩容大容量，多层分区设计特别贴心，主袋空间大，课本、作业本以及同款大容量笔盒轻松放；侧袋很深，放水杯、雨伞都很稳当；还有一个多功能收纳仓，钥匙、钱包这些小物件都能分类收纳，孩子自己就能收拾得明明白白，老母亲超省心✨讲真，选对高定包真的能让孩子轻松不少～戈撒驰这款书包，护脊、收纳、颜值全在线，真心推荐给各位家长！有需要的可以去了解下，让娃背得舒服，咱们也能少操心～#Gotyasatch护脊书包[话题]##戈撒驰护脊书包[话题]##gotyasatch书包[话题]##戈撒驰书包[话题]##德国戈撒驰书包[话题]# #小学生书包[话题]##护脊书包[话题]##大容量书包[话题]##护脊书包分享[话题]##初中生书包[话题]##大容量书包[话题]##高颜值书包[话题]##书包分享[话题]##育儿分享[话题]##书包选购指南[话题]# | E12: =LEN(D12) -> 1011 | F12: 113 | G12: 41 | H12: 26 | I12: 4 | J12: 184 | K12: 单眼皮男孩 | L12: 666266d500000000030300c2 | M12: 四川 | N12: 2025-06-29 08:47:44 | O12: https://www.xiaohongshu.com/user/profile/666266d500000000030300c2?&xsec_source=pc_note | P12: https://www.xiaohongshu.com/discovery/item/6860ac060000000010011302?app_platform=android&ignoreEngage=true&app_version=8.47.0&share_from_user_hidden=true&xsec_source=app_share&type=normal&xsec_token=CBmOjP91oxG2VSIOpAFjHVVW9C1xO9imdGNgeUqJYj478=&author_share=1 | Q12: Gotyasatch护脊书包,戈撒驰护脊书包,gotyasatch书包,戈撒驰书包,德国戈撒驰书包,小学生书包,护脊书包,大容量书包,护脊书包分享,初中生书包,高颜值书包,书包分享,育儿分享,书包选购指南 | R12: =VLOOKUP(A12,[1]蒲公英数据!A:H,8,0) -> 0.089902816 | S12: =VLOOKUP(A12,[1]蒲公英数据!A:I,9,0) -> 0.060744611 | T12: =VLOOKUP(A12,[1]蒲公英数据!A:J,10,0) -> 0.36799382
A13: 689566830000000022038b27 | B13: normal | C13: 有小升初娃，哪款初中生书包深得他心❓ | D13: 家有小升初娃的妈妈懂这种焦虑吗？作业堆成山⛰，书包天天沉得像“大石头”，Leo放学总吵着要我帮他背，我没背一会就压得后背生疼，真怕孩子长时间背下来把脊柱压变形…加上他这半年长高了不少，旧书包肩带短，勒脖子，太遭罪了！赶紧趁暑假换个护脊书包，入手了风很大的GMT和戈撒驰，分享Leo试背的真实感受，给同样要换初中生书包的宝妈们做个参考先说共同优点：两款包身都设计了反光条，走夜路很安全，而且用的环保面料，整体质感好，挺阔有型，背几年都不会坏~✨关键点（重点看！）1⃣身高定制戈撒驰：可根据身高定制，按身高自由调节，从140cm用到180cm！比如明年长高10cm，刻度尺一推就调好了，书包与孩子背部始终保持很好的贴合，护脊效果不会受到影响。既省了多次购置书包的钱，又避免频繁换书包让脊柱反复适应压力！GMT：150-180cm通用，没法按身高精细调2⃣护脊减负戈撒驰：内置U型铝制支撑杆+3D高弹背板，贴合孩子的脊柱曲线。Leo装满书背了两小时，他说背上像有手托着腰，跑跳都不晃，装同样的东西背着比旧书包轻多了大夏天也没闷汗，透气性在线～GMT：S型护脊铝条，背板偏硬挺，Leo背了半小时后背出现汗渍3⃣收纳功能戈撒驰：35L大容量，平时两个大口袋放书本作业够用了，扩容拉链一打开还能再装5L！Leo参加学校羽毛球校队训练时，球拍装进前袋就行，不用再额外背球包了，超方便GMT：30L日常够用，研究了下放不下运动器材，需要另外备口袋单独拎着一番对比下来，我们留了戈撒驰～Leo觉得它能放下他心爱的球拍，而我基于长期主义消费习惯更看重它的身高定制功能，用到初中毕业妥妥的，太适合“蹿个儿快+有运动需求”的娃了！我还买了他家配套的笔袋，容量超大超能装。给小升初娃选书包，护脊减负是底线，能适配成长是王道，不然买半年就小了，白花钱还伤脊柱！#Gotyasatch护脊书包[话题]# #戈撒驰护脊书包[话题]# #戈撒驰高定护脊书包[话题]# #gotyasatch书包[话题]# #戈撒驰书包[话题]# #德国戈撒驰书包[话题]# #小学生书包[话题]# #护脊书包[话题]# #大容量书包[话题]# #护脊书包分享[话题]# #初中生书包[话题]# #高颜值书包[话题]# #书包分享[话题]# #戈撒驰身高定制书包[话题]# | E13: =LEN(D13) -> 960 | F13: 163 | G13: 88 | H13: 26 | I13: 11 | J13: 288 | K13: 加油呀茜茜同学 | L13: 5c508caa0000000011011902 | M13: 湖北 | N13: 2025-08-08 04:00:39 | O13: https://www.xiaohongshu.com/user/profile/5c508caa0000000011011902?&xsec_source=pc_note | P13: https://www.xiaohongshu.com/discovery/item/689566830000000022038b27?app_platform=android&ignoreEngage=true&app_version=8.47.0&share_from_user_hidden=true&xsec_source=app_share&type=normal&xsec_token=CBnjRxmTkdR3m3KskfN9ZuNY7R69Wb4SP_Tg0hv5nfaWM=&author_share=1 | Q13: Gotyasatch护脊书包,戈撒驰护脊书包,戈撒驰高定护脊书包,gotyasatch书包,戈撒驰书包,德国戈撒驰书包,小学生书包,护脊书包,大容量书包,护脊书包分享,初中生书包,高颜值书包,书包分享,戈撒驰身高定制书包 | R13: =VLOOKUP(A13,[1]蒲公英数据!A:H,8,0) -> 0.10085634 | S13: =VLOOKUP(A13,[1]蒲公英数据!A:I,9,0) -> 0.057024645 | T13: =VLOOKUP(A13,[1]蒲公英数据!A:J,10,0) -> 0.35445662
A14: 686f276a0000000012017fa5 | B14: normal | C14: 孩子书包到底要不要买好点的呀？ | D14: 儿子暑假后上初中，整理他小学东西，发现书包带子磨亮了，底部也塌了。初中学业重、课本多，这旧书包肯定扛不住。前阵听邻居说，她家孩子上初中后背总疼，换了护脊书包才好点。我当时笑她讲究，现在摸着这硬邦邦的旧书包，有点慌：初中背这么多书，压着正在发育的脊椎，真不是小事。纠结要不要换个好点的护脊书包，可好点的像戈撒驰这种都上千块。怕省这点钱耽误孩子身体，可上千块买个书包又实在肉疼，这钱该花吗？#小升初[话题]# #护脊书包[话题]# #Gotyasatch护脊书包[话题]# | E14: =LEN(D14) -> 234 | F14: 88 | G14: 36 | H14: 84 | I14: 9 | J14: 217 | P14: https://www.xiaohongshu.com/explore/686f276a0000000012017fa5?xsec_token=MBmgL9GZA1UIy3NLUvDlO-zejatOmcBVY2z5GM7z875TQ=&xsec_source=pc_pgy | R14: =VLOOKUP(A14,[1]蒲公英数据!A:H,8,0) -> 0.094061217 | S14: =VLOOKUP(A14,[1]蒲公英数据!A:I,9,0) -> 0.023131111 | T14: =VLOOKUP(A14,[1]蒲公英数据!A:J,10,0) -> 0.35084175
A15: 68882cfa000000001d00d693 | B15: normal | C15: 职场妈妈育儿经|护脊书包真的不是智商税 | D15: Hi，宝子们～我是樱桃 ，39岁的职场妈妈家有即将四年级的小神兽去年发现孩子背书包走路总往前扯着身子走我这当妈的看着心疼！眼看就要开学，功课只会更重当务之急是给他选个真的能减负的护脊书包。做了一堆功课后果断入手戈撒驰护脊书包，现在用下来，真心觉得选对了！·最戳我的是它能根据身高定制内侧藏着身高刻度，140-180cm身高随意调，真实名副其实的“高”定包。我家娃现在160cm就算将来上了初中长到 180cm，这书包也能用。更重要的是，不管孩子长多高书包都能贴合他当下的身形！护脊效果丝毫不会打折扣毕竟合身才是护脊的基础呀！·光能跟着“长”还不够，护脊的核心得看支撑。它那U型铝制支撑杆我特意研究过不是硬邦邦的直杆而是能顺着孩子的脊椎曲线贴上去的。平时孩子跑跳后书本晃荡的力道全被这支架稳稳吸收了。难怪他说跑跳时比以前轻松多了再也没喊过后背震得疼～·支撑稳了，压力分散更关键这款的四点支撑设计是真科学：肩部顶部、臀腰部上方、稳定的底部，把原来全压在肩膀的重量，分摊到了胸部和腰部。再配上加宽加厚的肩带、高弹力背垫和厚实腰垫，孩子背着十斤书，也不会像以前那样往前扯着走了，现在每天放学回来既不喊肩膀酸，背也挺得直直的，看着就精神！·而且这款护脊书包是30+5L扩容大容量设计，就算将来当初中生书包用也妥妥够装。分区也特别贴心：主副隔层放课本和练习册伸缩袋放足球、衣服侧边放钥匙、校园卡、大水杯…以前他乱丢乱塞的毛病，居然被这书包治好了～他们家的大容量笔盒我也果断下单了包身用的是 PET 环保面料，防水耐造，孩子在学校疯玩也不怕磨坏最让我安心的是360°反光设计夜间出行安全感拉满·看着他背着书包走路昂首挺胸的样子，老母亲我终于松了口气给孩子一个挺拔身姿真可以从选对护脊书包开始呀～#Gotyasatch护脊书包[话题]# #戈撒驰护脊书包[话题]# #gotyasatch书包[话题]# #戈撒驰书包[话题]# #德国戈撒驰书包[话题]# #小学生书包[话题]# #护脊书包[话题]##大容量书包[话题]# #护脊书包分享[话题]# #初中生书包[话题]# #高颜值书包[话题]# #书包分享[话题]# #戈撒驰高定护脊书包[话题]# #戈撒驰身高定制书包[话题]# | E15: =LEN(D15) -> 933 | F15: 34 | G15: 16 | H15: 11 | I15: 1 | J15: 62 | K15: 樱桃在成长 | L15: 5b476eeb4eacab0e3e30ea10 | M15: 河南 | N15: 2025-07-29 12:12:47 | O15: https://www.xiaohongshu.com/user/profile/5b476eeb4eacab0e3e30ea10?&xsec_source=pc_note | P15: https://www.xiaohongshu.com/discovery/item/68882cfa000000001d00d693?app_platform=android&ignoreEngage=true&app_version=8.47.0&share_from_user_hidden=true&xsec_source=app_share&type=normal&xsec_token=CBtaPkwJ0ri0aNzuGoBEzszMILnoaeDo2Tar9e_6w514c=&author_share=1 | Q15: Gotyasatch护脊书包,戈撒驰护脊书包,gotyasatch书包,戈撒驰书包,德国戈撒驰书包,小学生书包,护脊书包,大容量书包,护脊书包分享,初中生书包,高颜值书包,书包分享,戈撒驰高定护脊书包,戈撒驰身高定制书包 | R15: =VLOOKUP(A15,[1]蒲公英数据!A:H,8,0) -> 0.063461338 | S15: =VLOOKUP(A15,[1]蒲公英数据!A:I,9,0) -> 0.018366678 | T15: =VLOOKUP(A15,[1]蒲公英数据!A:J,10,0) -> 0.33485433
A16: 688044c4000000002400aa45 | B16: normal | C16: 护脊书包决赛圈3选1！！！ | D16: 救命！给娃挑护脊书包挑到崩溃！扒了3款IGR认证的热门款，因为儿子小升初，想给他换个容量大点的，所以决定在贝克曼和戈撒驰护脊书包里选一个，看了一下，贝克曼实际减负效果有40%，而戈撒驰有64.8%，但贝克曼好看，戈撒驰减负效果好...纠结得头都要秃了，想一步到位，有没有真实用过的宝妈分享下经验，评论区等答案！！！#护脊书包[话题]# #真实评价[话题]# #性价比[话题]# #戈撒驰书包[话题]# #宝妈求助[话题]# #Gotyasatch护脊书包[话题]# | E16: =LEN(D16) -> 232 | F16: 112 | G16: 98 | H16: 55 | I16: 26 | J16: 291 | K16: 元气兄弟冲冲冲 | L16: 573701b55e87e751134d5118 | M16: 广西 | N16: 2025-07-23 08:19:26 | O16: https://www.xiaohongshu.com/user/profile/573701b55e87e751134d5118?&xsec_source=pc_note | P16: https://www.xiaohongshu.com/discovery/item/688044c4000000002400aa45?app_platform=android&ignoreEngage=true&app_version=8.47.0&share_from_user_hidden=true&xsec_source=app_share&type=normal&xsec_token=CBVPyoiYuODusAoczjBSjhPOApJzV5RwMRUMWyxTgc7zM=&author_share=1 | Q16: 护脊书包,真实评价,性价比,戈撒驰书包,宝妈求助,Gotyasatch护脊书包 | R16: =VLOOKUP(A16,[1]蒲公英数据!A:H,8,0) -> 0.11908684 | S16: =VLOOKUP(A16,[1]蒲公英数据!A:I,9,0) -> 0.014035442 | T16: =VLOOKUP(A16,[1]蒲公英数据!A:J,10,0) -> 0.31633041
A17: 686207780000000012017b62 | B17: normal | C17: 小学生护脊训练要注意什么｜护脊书包&心得 | D17: 一直都有提醒孩子作业要端正坐姿，但四年级学校脊柱侧弯筛查依然：右肩高和肩胛骨有点高低不平。四年级真是不太平的一年，近视，脊柱疑似侧弯。作为曾在母婴行业摸爬滚打数年及常年翻看育儿书的妈妈，隐隐还是焦虑了。好在这段时间我们坚持做力量训练，单杠、俯卧撑、跑步锻炼，慢慢矫正过来一些了。脊柱侧弯不是小问题，平时一定要做好护脊工作，分享几个护脊方法：1️⃣姿势禁忌✖️歪扭坐。写作业时长期外向一侧，比如托腮，斜趴，这样单侧椎体压力增加，容易加重旋转侧弯✔️改用坐姿矫正椅或使用腰部支撑垫，另坐姿和座椅要调整合适（详见图3）✖️瘫软躺。窝在沙发里刷手机，蜷缩成C型看电视，加剧椎体形变风险✔️改用靠墙或沙发直立坐，保持耳肩髋垂直2️⃣负重禁忌✖️背软榻、后坠、无护脊设计的书包，必须往前倾才能走路保持平衡，容易弯腰驼背✔️换成护脊书包，挑选重点看这三点：·背部需有支撑系统·必须包含「三点式固定」（胸扣、腰扣、肩带）·收纳分区，避免书本散落导致重心偏移护脊书包自用分享：我们目前背的是戈撒驰护脊书包，这个书包可以根据身高进行定制，可以说是“高”定包身高在140cm-180cm可以随意调节。书包内置了U型铝制支撑杆，符合人体工学设计，贴合孩子背部，防止书包挤压脊柱。调到合适的刻度，正确背负后将肩部重量分散至腰背部，走路轻便的，不再弯腰驼背！30L大容量，合理分层，收纳方便，作业、书本、水杯、雨伞都有相应的放置区域。Y字形蜂窝网面和背垫中空凹槽设计，清爽不闷汗，像深圳的天气比较潮热，孩子背着也挺舒服的。环保面料+防水设计，耐用又抗造。包身还有反光条设计，过马路夜间出行很安全！他们家同款的笔盒我也买了，容量也非常大。Ps：买书包最好带娃试背一下，装3-5本书让他走两圈，观察是否驼背、耸肩。最后，脊柱这事没有后悔药，还是要尽早干预。#Gotyasatch护脊书包[话题]# #戈撒驰护脊书包[话题]# #gotyasatch书包[话题]# #戈撒驰书包[话题]# #德国戈撒驰书包[话题]# #小学生书包[话题]# #护脊书包[话题]# #护脊书包分享[话题]# #初中生书包[话题]# #大容量书包[话题]# #高颜值书包[话题]# #书包分享[话题]# #育儿[话题]# | E17: =LEN(D17) -> 933 | F17: 33 | G17: 27 | H17: 8 | I17: 6 | J17: 74 | K17: 妞宝妈妈 | L17: 5b6faba97979810001d49e26 | M17: 广东 | N17: 2025-06-30 05:45:36 | O17: https://www.xiaohongshu.com/user/profile/5b6faba97979810001d49e26?&xsec_source=pc_note | P17: https://www.xiaohongshu.com/discovery/item/686207780000000012017b62?app_platform=android&ignoreEngage=true&app_version=8.47.0&share_from_user_hidden=true&xsec_source=app_share&type=normal&xsec_token=CBepcPxEIB7gbBLY5im--WcDZ8v8xYN3ZlFHvazRbJlq4=&author_share=1 | Q17: Gotyasatch护脊书包,戈撒驰护脊书包,gotyasatch书包,戈撒驰书包,德国戈撒驰书包,小学生书包,护脊书包,护脊书包分享,初中生书包,大容量书包,高颜值书包,书包分享,育儿 | R17: =VLOOKUP(A17,[1]蒲公英数据!A:H,8,0) -> 0.074371354 | S17: =VLOOKUP(A17,[1]蒲公英数据!A:I,9,0) -> 0.021098188 | T17: =VLOOKUP(A17,[1]蒲公英数据!A:J,10,0) -> 0.31220794
A18: 68887fba000000000403e00e | B18: normal | C18: 两款护脊书包实测！减负护脊+身高定制 | D18: 自从儿子参加走秀后，我对他的体态越发关注。而且他马上要上五年级了，学业加重，书包也越来越沉，所以我想给他找一款真正能减压、能帮助维持好体态，且能长期使用的护脊书包。锁定到戈撒驰和GMT，猜猜选了哪一款❓身高定制挑书包时，我很关注能不能贴合身形——孩子长得快，今年合适的书包明年可能就不合身了。戈撒驰可根据身高定制 ：140-180cm身高随意调节，不愧是“高”定包，孩子长个，书包也能跟着“长”，能很好地贴合脊柱曲线，帮着培养好体态，而且等上了初中，也能当初中生书包用~护脊减负•戈撒驰：U型铝制支撑杆+背板，不仅能更好地贴合孩子脊柱曲线，还能吸收来自书包的撞击力；再加上四点承托设计，让肩部、胸部、腰部形成多点受力，把肩部重量分散到腰背部，专业检测减负效果达64.8%，儿子背上后舒服又减压，身姿都挺拔不少~•GMT：S型铝条+EVA背板，能为背部提供支撑，但我没找到具体的减负数据。科学分区收纳两款书包都是30L的，不过在细节上不同：•戈撒驰：两个隔层+多功能收纳仓+侧兜，分区清晰，无论是课本、配套大容量笔袋、水杯，还是钥匙、校园卡都能轻松收纳，找东西时一目了然，当初中生书包用也很合适。•GMT：双隔层设计+前袋，分区比较简单，日常使用也够用。细节•反光条设计：两款包身都有360°反光条，但戈撒驰面积稍大一些，夜里很显眼，儿子说亮起来像蜘蛛侠哈哈~简单来说，如果想从小学用到初中，追求身高定制和多功能性，戈撒驰是很合适的选择。#Gotyasatch护脊书包[话题]# #戈撒驰护脊书包[话题]# #gotyasatch书包[话题]# #戈撒驰书包[话题]# #德国戈撒驰书包[话题]# #小学生书包[话题]# #护脊书包[话题]# #戈撒驰高定护脊书包[话题]# #大容量书包[话题]# #护脊书包分享[话题]# #初中生书包[话题]# #高颜值书包[话题]# #书包分享[话题]# #戈撒驰身高定制书包[话题]# | E18: =LEN(D18) -> 812 | F18: 117 | G18: 68 | H18: 11 | I18: 4 | J18: 200 | K18: Gordon加油呀 | L18: 57844d613460944b23bbb350 | M18: 江苏 | N18: 2025-07-29 09:48:49 | O18: https://www.xiaohongshu.com/user/profile/57844d613460944b23bbb350?&xsec_source=pc_note | P18: https://www.xiaohongshu.com/discovery/item/68887fba000000000403e00e?app_platform=android&ignoreEngage=true&app_version=8.47.0&share_from_user_hidden=true&xsec_source=app_share&type=normal&xsec_token=CBtaPkwJ0ri0aNzuGoBEzszNj-lXpKNeZChWWcUamTztI=&author_share=1 | Q18: Gotyasatch护脊书包,戈撒驰护脊书包,gotyasatch书包,戈撒驰书包,德国戈撒驰书包,小学生书包,护脊书包,戈撒驰高定护脊书包,大容量书包,护脊书包分享,初中生书包,高颜值书包,书包分享,戈撒驰身高定制书包 | R18: =VLOOKUP(A18,[1]蒲公英数据!A:H,8,0) -> 0.10147878 | S18: =VLOOKUP(A18,[1]蒲公英数据!A:I,9,0) -> 0.044270233 | T18: =VLOOKUP(A18,[1]蒲公英数据!A:J,10,0) -> 0.308639
A19: 685ff26e000000002201f348 | B19: normal | C19: 小升初|背上护脊书包，学习健康两抓手！ | D19: 当家长的谁不盼着孩子学习一路提升？为了帮娃提高成绩，我可没少下功夫！像把学习大目标拆成每天的小任务，孩子做完有成就感；用思维导图把知识点串起来，复习时一目了然；整理错题本定期复盘，薄弱点各个击破；再搭配“番茄钟”学习法，学25分钟歇5分钟，培养孩子时间观念；平时还和孩子玩知识问答，边玩边巩固知识。这些方法确实管用，但后来我才发现，想让孩子专注学习，一个舒服的书包太重要了！我家孩子小升初课业量直线上升，每天看着她背着沉甸甸的书包，弯着小身板进出家门，当妈的心里直泛酸。直到我才知道，书包没选对，不仅让孩子肩膀酸痛，连学习状态都会受影响——背着硌得慌的书包，哪还有心思认真听课写作业呀？为了给孩子挑个靠谱的初中生书包，我做了超多功课，最后才入手了戈撒驰护脊书包！✅小升初家长最头疼的就是孩子长得快，书包总换新。戈撒驰这款护脊书包「会跟着长个儿」，后背隐藏的身高刻度能从140cm调到180cm，根据孩子身高自由定制，叫它“高”定包不过分吧从初一背到高中都不用换。✅它的护脊设计绝了！U型铝制支架搭配立体背板，就像给脊柱装了「隐形支撑」，装满书也不会下坠塌腰。加上四点支撑设计能把重量稳稳“分摊”到肩膀、腰部、底部这些地方。只要正确背负，专业实测64.8%的减负效果，10斤书包背出3斤轻感，孩子跑跳时书包稳稳贴背不晃悠，真正做到了把压力“卸”到该去的地方！✅细节设计也很贴心：35L大容量，分区合理，课本、作业、笔盒(空间大，有多层可以收纳)轻松装下，侧兜拿雨伞、水杯也超方便~孩子初中要带的东西多，书包全都能装下；PET防水面料很抗造，不怕雨淋，久用如新；3D蜂窝背垫超透气，夏天背也不闷汗；蝴蝶型宽肩带柔软厚实，孩子再也没喊过肩膀疼。今天带孩子参加初中新生活动，它派上大用场了。真心建议家长别只盯着孩子成绩，书包里装的不仅是书本，更是孩子的健康！选对书包才是给孩子的成长上了把 “安全锁”#Gotyasatch护脊书包[话题]# #戈撒驰护脊书包[话题]# #gotyasatch书包[话题]# #戈撒驰书包[话题]# #德国戈撒驰书包[话题]# #小学生书包[话题]# #护脊书包[话题]# #大容量书包[话题]##护脊书包分享[话题]##初中生书包[话题]##高颜值书包[话题]##书包分享[话题]# #小升初[话题]# #开学装备[话题]# | E19: =LEN(D19) -> 975 | F19: 174 | G19: 63 | H19: 31 | I19: 27 | J19: 295 | K19: 乔治是妹妹 | L19: 62ee531500000000150190a6 | M19: 上海 | N19: 2025-06-28 15:07:01 | O19: https://www.xiaohongshu.com/user/profile/62ee531500000000150190a6?&xsec_source=pc_note | P19: https://www.xiaohongshu.com/discovery/item/685ff26e000000002201f348?app_platform=android&ignoreEngage=true&app_version=8.47.0&share_from_user_hidden=true&xsec_source=app_share&type=video&xsec_token=CByVGjdCyJUAQ0ap4ht4LQEQ1ahufgr6iyaCCyeK6z-4Y=&author_share=1 | Q19: Gotyasatch护脊书包,戈撒驰护脊书包,gotyasatch书包,戈撒驰书包,德国戈撒驰书包,小学生书包,护脊书包,大容量书包,护脊书包分享,初中生书包,高颜值书包,书包分享,小升初,开学装备 | R19: =VLOOKUP(A19,[1]蒲公英数据!A:H,8,0) -> 0.11124251 | S19: =VLOOKUP(A19,[1]蒲公英数据!A:I,9,0) -> 0.022072937 | T19: =VLOOKUP(A19,[1]蒲公英数据!A:J,10,0) -> 0.27831218
A20: 686205f70000000022033695 | B20: normal | C20: 买晚了后悔才知道护脊书包能爆改体态 | D20: 现在小学生的负担真的好重啊每天书包都沉甸甸的，整个人被压得弯腰驼背之前我还以为书包都大差不差，就随便选了个图案好看的结果孩子每天都说书包重肩膀痛用了一阵子之后，甚至体态都变差了️我赶紧做了功课，了解到原来孩子的脊柱正处于成长发育阶段普通书包没有护脊功能，长期背负还会导致脊柱侧弯等到那时后悔可就来不及了！对比了市面上的护脊书包品牌，我最终入手了了德国品牌戈撒驰看到很多家长给孩子选的初中生书包也是这款果然用过后我也懂了科学+专业的魅力！-它内置的U型铝制支撑杆，是高级登山包才有的设计符合人体工学，更贴合孩子的背部曲线有效吸收书包内部的压力和撞击力背起来书包不往下坠，孩子的脊椎就不会被拉扯到啦！后背隐藏了身高刻度，从140-180cm可以根据身高定制妥妥的“高”定包毕竟孩子长得快，这下不用频繁给他换书包了我们家老人有次去接孩子的时候，孩子非得秀一把把身高刻度调到爷爷能背的位置后，爷爷背上身到家坐下才想起还背着包呢说是太轻了没什么感觉就忘记了，咱小时候可没见过这好东西-调到适合高度后，背上书包扣上肩扣、腰扣、胸扣一整套正确背负流程完成，我家孩子的体态明显跟以往不一样他也很惊讶：“妈妈，这个书包背起来好轻松”以前的书包肩带又窄又细重量全压在肩膀上，难受不说，身子只能一直往前倾现在这款护脊书包可以压力分散给腰臀背部，整体自然就轻了而且肩带加厚加宽，背垫是高弹的3D 眼蜂窝网面+中空凹槽设计不仅不勒肩膀、舒适好背，夏天久背也清爽不闷汗-容量更是没得说，足足35L超能装！2 个主隔层加1个容量扩展袋日常的书本、作业、笔袋、饭盒都能放侧边装水杯、雨伞、钥匙等，分层合理，收纳便捷我还入了他家配套笔盒，超大容量，各种笔、修正带、胶带啥的都能装PET环保面料，扎实但是不硬邦邦，手感很好！-来自育婴师的总结！护脊书包真不是智商税除了学业成绩外，身体发育也需要我们关注！#Gotyasatch护脊书包[话题]# #戈撒驰护脊书包[话题]# #gotyasatch书包[话题]# #戈撒驰书包[话题]# #德国戈撒驰书包[话题]# #小学生书包[话题]# #护脊书包[话题]# #大容量书包[话题]# #护脊书包分享[话题]# #初中生书包[话题]# #高颜值书包[话题]# #书包分享[话题]# | E20: =LEN(D20) -> 946 | F20: 372 | G20: 143 | H20: 8 | I20: 60 | J20: 583 | K20: 希希bb | L20: 5c03e36d0000000008010ddc | M20: 江西 | N20: 2025-06-30 06:39:08 | O20: https://www.xiaohongshu.com/user/profile/5c03e36d0000000008010ddc?&xsec_source=pc_note | P20: https://www.xiaohongshu.com/discovery/item/686205f70000000022033695?app_platform=android&ignoreEngage=true&app_version=8.47.0&share_from_user_hidden=true&xsec_source=app_share&type=normal&xsec_token=CBepcPxEIB7gbBLY5im--WcH9goP1Q85U347_A4Af3194=&author_share=1 | Q20: Gotyasatch护脊书包,戈撒驰护脊书包,gotyasatch书包,戈撒驰书包,德国戈撒驰书包,小学生书包,护脊书包,大容量书包,护脊书包分享,初中生书包,高颜值书包,书包分享 | R20: =VLOOKUP(A20,[1]蒲公英数据!A:H,8,0) -> 0.094638407 | S20: =VLOOKUP(A20,[1]蒲公英数据!A:I,9,0) -> 0.075674294 | T20: =VLOOKUP(A20,[1]蒲公英数据!A:J,10,0) -> 0.27543589
A21: 6874b616000000001d00d4bb | B21: normal | C21: 小高年级护脊书包怎么选？成长适配很重要～ | D21: 乐宝六年级了，书包沉得像背砖头，怕影响体态我赶紧做功课，发现很多家长纠结“书包本身轻不轻”，其实本身重量不是关键，搞懂护脊和减负原理才能理性选择。把热门的两款护脊书包都买回来试试，真实体验分享给你们！身高调节◽️戈撒驰：后背内侧隐藏有身高刻度，这点真的很戳我，140-180cm可调。根据身高调好后书包刚好贴在腰上，跑着追同学书包都不晃◽️GMT：尺寸固定，适合150-180cm护脊+减负设计◽️戈撒驰：U型铝制支撑杆+背板，符合人体工学，像有手托着，很轻松就挺直了背。采用“分压式”实现有效减负，加宽加厚肩带、高弹背垫、加厚腰垫，将集中在肩部的压力分散到腰背部，十斤的书包背出三斤实感，专业数据显示减负能达64.8%！◽️GMT：S型护脊铝条+EVA压模背板，支撑性不错。乐宝说背起来也比旧书包轻容量空间◽️戈撒驰：35L扩容大容量。我特意数了下分区：主隔层装书本作业，副隔层放练习册，多隔层里的小格子刚好塞笔袋、修正带、公交卡，还有多功能前袋——乐宝的羽毛球拍也能塞进去，侧面网兜能放跳绳，物品合理收纳，翻包不乱，所以他们很能装的笔盒我也买回来了◽️GMT：30L容量，分层比较简单：主隔层+前隔层，前面两个小拉链袋可以放文具，但我试了下大件物品不太容易放进去面料/细节两款都是环保面料，戈撒驰包身的反光条面积个人认为大，夜晚出行很安全，侧边袋用了防盗的锁扣和拉链设计，以防丢失东西，手提带也厚实，拎起来不勒手，可以说细节满满了。综合体验两款都是IGR认证的护脊书包，但戈撒驰按身高自由调节这点很打动我，不像衣服一样“穿半年就小”，当初中生书包都没问题，加上实用性比较强，最后和孩子一致选了戈撒驰这款。#Gotyasatch护脊书包[话题]# #戈撒驰护脊书包[话题]# #gotyasatch书包[话题]# #戈撒驰书包[话题]# #德国戈撒驰书包[话题]# #小学生书包[话题]# #护脊书包[话题]# #大容量书包[话题]# #护脊书包分享[话题]# #初中生书包[话题]# #高颜值书包[话题]# #书包分享[话题]# #戈撒驰高定护脊书包[话题]# #戈撒驰身高定制书包[话题]# | E21: =LEN(D21) -> 898 | F21: 221 | G21: 169 | H21: 16 | I21: 22 | J21: 428 | K21: 乐妈 | L21: 5b27d5ebf7e8b932b7fc8145 | M21: 广东 | N21: 2025-07-14 08:47:44 | O21: https://www.xiaohongshu.com/user/profile/5b27d5ebf7e8b932b7fc8145?&xsec_source=pc_note | P21: https://www.xiaohongshu.com/discovery/item/6874b616000000001d00d4bb?app_platform=android&ignoreEngage=true&app_version=8.47.0&share_from_user_hidden=true&xsec_source=app_share&type=normal&xsec_token=CBqEcsQbAMDcIK66kbNAcTgRo1wYYfUyrFvO-DGXUHD5o=&author_share=1 | Q21: Gotyasatch护脊书包,戈撒驰护脊书包,gotyasatch书包,戈撒驰书包,德国戈撒驰书包,小学生书包,护脊书包,大容量书包,护脊书包分享,初中生书包,高颜值书包,书包分享,戈撒驰高定护脊书包,戈撒驰身高定制书包 | R21: =VLOOKUP(A21,[1]蒲公英数据!A:H,8,0) -> 0.1288998 | S21: =VLOOKUP(A21,[1]蒲公英数据!A:I,9,0) -> 0.047560704 | T21: =VLOOKUP(A21,[1]蒲公英数据!A:J,10,0) -> 0.26018969
A22: 6888790800000000250241aa | B22: normal | C22: 四年级预备役✨两款热门护脊书包选谁 | D22: 在天津教育重点区陪读三年，我算悟了：小学生的脊柱，得从小护着。​以前别人说护脊书包好，我不以为然，直到看到Ruby天天背着重书包弯腰驼背走，真怕久了伤脊柱啊。赶紧做功课入了G/M/T和戈撒驰，真实经验分享给你们～✅首先是身高定制：戈撒驰的书包内侧有身高刻度尺，140~180cm身高都能调~是名副其实的“高”定包，不用担心之后长高了背不了，而且书包的面料摸着很扎实，了解了一下是比较抗造的，用到初中当初中生书包都可以。G/M/T 150-180cm通用✅然后是减负：戈撒驰用了专业登山包同款的U型铝制支撑杆，搭配3D透气背板，能稳稳包裹住背部。再加上加厚肩带、可调节胸扣、腰扣和加厚腰垫，把原来压在肩膀的重量分散到腰上和背上，经专业测试显示减压效果达64.8%，Ruby也说现在背着书包感觉可轻松了~G/M/T是S型铝条+ EVA压膜背板，支撑性也不错✅在容量上，两款都是30L，不过收纳有区别：戈撒驰：分层合理且实用，2个主隔层+1个多功能收纳仓+侧兜。Ruby带的东西多的时候，主隔层放美术、科学课的大件用具，副隔层放课本作业本；多功能仓里放发圈、校园卡口罩啥的收纳得很好；侧兜放水杯，拿取方便。G/M/T：一个大的主仓+副隔层+前袋+侧兜，日常也够用了。综合下来，我们选了戈撒驰：身高定制、科学减压、收纳合理，既不用年年换书包，又能护着孩子的脊柱。换包后，看着Ruby从含胸驼背到抬头挺胸，感觉真的选对了～#Gotyasatch护脊书包[话题]# #戈撒驰护脊书包[话题]# #gotyasatch书包[话题]# #戈撒驰书包[话题]# #德国戈撒驰书包[话题]# #小学生书包[话题]# #护脊书包[话题]# #大容量书包[话题]# #护脊书包分享[话题]# #初中生书包[话题]# #高颜值书包[话题]# #书包分享[话题]# #戈撒驰高定护脊书包[话题]# #戈撒驰身高定制书包[话题]# | E22: =LEN(D22) -> 800 | F22: 55 | G22: 23 | H22: 42 | I22: 3 | J22: 123 | K22: 哏都Ruby妈妈 | L22: 5bc9af3ebe7e3e0001207a3e | M22: 天津 | N22: 2025-07-29 11:36:44 | O22: https://www.xiaohongshu.com/user/profile/5bc9af3ebe7e3e0001207a3e?&xsec_source=pc_note | P22: https://www.xiaohongshu.com/discovery/item/6888790800000000250241aa?app_platform=android&ignoreEngage=true&app_version=8.47.0&share_from_user_hidden=true&xsec_source=app_share&type=normal&xsec_token=CBtaPkwJ0ri0aNzuGoBEzszCMZuOmncJtKEBdBShtRpA8=&author_share=1 | Q22: Gotyasatch护脊书包,戈撒驰护脊书包,gotyasatch书包,戈撒驰书包,德国戈撒驰书包,小学生书包,护脊书包,大容量书包,护脊书包分享,初中生书包,高颜值书包,书包分享,戈撒驰高定护脊书包,戈撒驰身高定制书包 | R22: =VLOOKUP(A22,[1]蒲公英数据!A:H,8,0) -> 0.075997869 | S22: =VLOOKUP(A22,[1]蒲公英数据!A:I,9,0) -> 0.043405676 | T22: =VLOOKUP(A22,[1]蒲公英数据!A:J,10,0) -> 0.24963557
A23: 68836875000000002001a367 | B23: normal | C23: 151cm女生亲测❗热门护脊书包到底选哪款？ | D23: 家有五升六且酷爱户外活动的女娃一枚，无论是学习还是出去玩都得装一大堆东西，老母亲瞅着她弯腰驼背就焦虑，于是疯狂研究护脊书包！精挑细选了N多好评的两款：戈撒驰和贝克曼，今天刚好让娃背到户外实测下~先划重点❗ 【适配成长】很关键这个年龄段的孩子长个子比较快，书包用不了多久就因为背着有点勒而需要更换。戈撒驰是140-180cm背板根据身高自由调节，孩子长个了，自己调就行。贝克曼尺寸固定，适合140-175cm❥ 护脊≠越轻越好！减负设计对比戈撒驰【减压达64.8%】采用U型铝制支撑杆，贴合孩子背部曲线，结合3D背板，防止书包负重变形挤压脊柱，正确背负后重量通过肩带、胸带、腰带分散到腰背，娃身板挺得直直的，跑跳都不晃动~✨⚫️贝克曼【减压达40%】内置S型铝条贴合背部，背负系统也算稳❥ 产品细节对比戈撒驰：德国PET环保面料，冰川蓝+拼牛皮的外观，质感高级又养眼；30L大容量，分区细致且合理，三层大口袋，出游用的水杯、雨伞、零钱都能一一放置；隐藏式拉链，防水效果更好；手提带厚实不勒手，包身设计得有反光条，夜晚出行很安全。正面还有可替换的标记带，挂孩子心仪的卡通挂饰、徽章，配套的大容量笔袋也是美观又实用✨⚫️贝克曼：聚酯纤维面料，分区有两个大的主口袋，前兜收纳小物件。两款护脊书包各有各的好，但戈撒驰随身高定制和科学减负这两点太对老母亲的胃口了。毕竟娃长得快，能跟着调节才不浪费，小升初就可以直接当初中生书包用啦[赞R]#Gotyasatch护脊书包[话题]# #戈撒驰护脊书包[话题]# #gotyasatch书包[话题]# #戈撒驰书包[话题]# #德国戈撒驰书包[话题]# #小学生书包[话题]# #护脊书包[话题]# #大容量书包[话题]# #护脊书包分享[话题]# #初中生书包[话题]# #高颜值书包[话题]# #书包分享[话题]# #戈撒驰高定护脊书包[话题]# #戈撒驰身高定制书包[话题]# | E23: =LEN(D23) -> 807 | F23: 28 | G23: 12 | H23: 10 | I23: 10 | J23: 60 | K23: 李小慢Ella | L23: 5bfcfda38086b80001c79466 | M23: 湖北 | N23: 2025-07-26 09:55:49 | O23: https://www.xiaohongshu.com/user/profile/5bfcfda38086b80001c79466?&xsec_source=pc_note | P23: https://www.xiaohongshu.com/discovery/item/68836875000000002001a367?app_platform=android&ignoreEngage=true&app_version=8.47.0&share_from_user_hidden=true&xsec_source=app_share&type=normal&xsec_token=CBuSUtunJk9YTYeP1cz6p25tlEBbu8yerxTpiQ994jaXI=&author_share=1 | Q23: Gotyasatch护脊书包,戈撒驰护脊书包,gotyasatch书包,戈撒驰书包,德国戈撒驰书包,小学生书包,护脊书包,大容量书包,护脊书包分享,初中生书包,高颜值书包,书包分享,戈撒驰高定护脊书包,戈撒驰身高定制书包 | R23: =VLOOKUP(A23,[1]蒲公英数据!A:H,8,0) -> 0.087677145 | S23: =VLOOKUP(A23,[1]蒲公英数据!A:I,9,0) -> 0.010996684 | T23: =VLOOKUP(A23,[1]蒲公英数据!A:J,10,0) -> 0.24772516
A24: 6882b44a0000000011002c65 | B24: normal | C24: 初中生书包怎么选 | 看完再买也不迟❗ | D24: 我家孩子小升初想要一个新书包，小小愿望我当然要满足，每次给孩子选书包我都特纠结，他现在是成长关键期，学业压力又重！书包选不对，可能直接影响孩子脊椎发育，导致驼背、脊柱侧弯等！所以这次买初中生书包我做了全面功课，一次性给娃安排两个护脊书包！首先是隐藏的小细节，戈撒驰内侧有个身高刻度尺，可以按照身高调节到140-180cm的任何尺寸，书包不用一年一换这个点真的很戳我，能根据身高定制的 “高”定包，既省钱又省事~其次是护脊设计，戈撒驰的U型铝制支撑杆刚好贴合人体脊柱自然曲线，孩子背上身，腰背能自然挺起来，不用我再盯着纠正姿势。壳曼的仿生 S 型支架也不错，支撑力均匀，贴合度在线。减负设计上，戈撒驰减负原理是通过肩部+胸部+腰部多点承托让重量分散，娃说书包好像会“变魔术”，背上身真的感觉变轻了！容量也要关注，两款书包都是35L。戈撒驰30+5L的扩容设计，应用起来很灵活，对于东西多的孩子：书本、课外书、小零食、水杯、雨伞等，分层收纳很重要，它还有个前袋，打开能放下足球、衣服、网球拍等。同款大容量笔盒我也买了，很实用。透气和材质都没话说，网面设计不闷汗，戈撒驰的PET环保面料和贝克曼的聚酯纤维都防泼水，弄脏了擦一擦就好。两款护脊书包各有特点，功能方面都不错，选择权交给孩子了，他喜欢戈撒驰，大容量，背着舒服，按身高调节这个点咱当家长的更无法拒绝，直接给安排上！#Gotyasatch护脊书包[话题]# #戈撒驰护脊书包[话题]# #gotyasatch书包[话题]# #戈撒驰高定护脊书包[话题]# #戈撒驰身高定制书包[话题]##戈撒驰书包[话题]# #德国戈撒驰书包[话题]# #小学生书包[话题]# #护脊书包[话题]# #大容量书包[话题]# #护脊书包分享[话题]# #初中生书包[话题]# #高颜值书包[话题]# #书包分享[话题]# | E24: =LEN(D24) -> 776 | F24: 522 | G24: 120 | H24: 20 | I24: 21 | J24: 683 | K24: 一只金奶油 | L24: 5d8d089f0000000001008901 | M24: 山西 | N24: 2025-07-28 05:44:56 | O24: https://www.xiaohongshu.com/user/profile/5d8d089f0000000001008901?&xsec_source=pc_note | P24: https://www.xiaohongshu.com/discovery/item/6882b44a0000000011002c65?app_platform=android&ignoreEngage=true&app_version=8.47.0&share_from_user_hidden=true&xsec_source=app_share&type=video&xsec_token=CBINno8UndG9QBayMpJ-Jf7IM6H-gKQ-ldlsWC6rIcBwo=&author_share=1 | Q24: Gotyasatch护脊书包,戈撒驰护脊书包,gotyasatch书包,戈撒驰高定护脊书包,戈撒驰身高定制书包,戈撒驰书包,德国戈撒驰书包,小学生书包,护脊书包,大容量书包,护脊书包分享,初中生书包,高颜值书包,书包分享 | R24: =VLOOKUP(A24,[1]蒲公英数据!A:H,8,0) -> 0.20131653 | S24: =VLOOKUP(A24,[1]蒲公英数据!A:I,9,0) -> 0.04860159 | T24: =VLOOKUP(A24,[1]蒲公英数据!A:J,10,0) -> 0.23473734
A25: 689abe2a0000000023023cf8 | B25: normal | C25: 哥哥的初中生书包，妹妹也能背？真护脊减负 | D25: 作为职场妈妈，公司上升期的加班常态让我总被问：“这么忙，哪来时间陪孩子？”虽常与deadline赛跑‍♀️，但孩子从启蒙到兴趣班，我从未缺席。工作再忙，孩子的成长也不能错过。除了学业，我更关注他们的身心健康当我发现孩子们开始有点驼背，学校的体检结果显示脊柱侧弯、高低肩的时候，真的慌了，赶紧恶补护脊知识，除了通过运动纠正体态，考虑到哥哥今年小升初，我决定给他选个护脊书包当初中生书包。选书包时，哥哥一眼看中戈撒驰护脊书包。这个身高定制书包是身高在140-180cm之间随意调节，妥妥的“高”定包。哥哥现在162cm，对应调节后书包背上和后背很贴合。妹妹看到了也想背上试试，哥哥就按照妹妹147cm身高调整刻度，结果妹妹背上也很合适。再加上我们家的惯例，哥哥有的，妹妹也要有，所以按照妹妹喜欢的款式也给她买了一个坦白说我一开始内心是质疑孩子们自己选择的书包的，结果收到后，孩子们hin满意，背上以后身形也挺拔了，少年该有的朝气蓬勃也回来了，原来肤浅的是我，戈撒驰护脊书包是真的与众不同具体来说：首先纠正一下，不是所有号称护脊的书包都是真正科学护脊的！护脊得看整体结构设计，像戈撒驰护脊书包用的是符合人体工学的U型铝制支撑杆，它可以模拟人体脊柱自然曲线，更好地贴合孩子的背部，搭配高弹背板形成稳固支撑。其次，选护脊书包不能只看自重。轻的书包后背无支撑点，背起来松垮，书包的负重集中在肩膀，容易造成驼背‍♂️。戈撒驰护脊书包通过合理调节肩带+胸带+腰带，将重量分散到腰背部，真正实现减负护脊。35L扩容设计超实用：妹妹日常用30L足够，哥哥升初中后拉开扩容拉链，35L容量轻松应对增多的课业。主副隔层装书本作业，侧边袋放水杯雨伞，前袋能塞外套、足球，细节满分。他们家笔盒的容量也很大，所以也给兄妹俩一人准备了一个~ 环保面料耐磨防水，小剐蹭根本不怕，目测能用好几年，直接实现长期主义。育儿从尊重孩子的选择开始，尤其是每天都要用到的书包，他们的亲身使用感受是最重要✌️#Gotyasatch护脊书包[话题]##戈撒驰护脊书包[话题]##gotyasatch书包[话题]##戈撒驰书包[话题]##德国戈撒驰书包[话题]##护脊书包[话题]##大容量书包[话题]##初中生书包[话题]##戈撒驰高定护脊书包[话题]##戈撒驰身高定制书包[话题]# | E25: =LEN(D25) -> 967 | F25: 125 | G25: 75 | H25: 51 | I25: 3 | J25: 254 | K25: 小钟懿和她的哥哥 | L25: 624a82340000000021027c9f | M25: 广东 | N25: 2025-08-13 08:12:27 | O25: https://www.xiaohongshu.com/user/profile/624a82340000000021027c9f?&xsec_source=pc_note | P25: https://www.xiaohongshu.com/discovery/item/689abe2a0000000023023cf8?app_platform=android&ignoreEngage=true&app_version=8.47.0&share_from_user_hidden=true&xsec_source=app_share&type=normal&xsec_token=CB2JVBhkhZZHc4nm_UrUPu_-Xi2dUXADY4tUQqN_GY8b8=&author_share=1 | Q25: Gotyasatch护脊书包,戈撒驰护脊书包,gotyasatch书包,戈撒驰书包,德国戈撒驰书包,护脊书包,大容量书包,初中生书包,戈撒驰高定护脊书包,戈撒驰身高定制书包 | R25: =VLOOKUP(A25,[1]蒲公英数据!A:H,8,0) -> 0.10625292 | S25: =VLOOKUP(A25,[1]蒲公英数据!A:I,9,0) -> 0.069639416 | T25: =VLOOKUP(A25,[1]蒲公英数据!A:J,10,0) -> 0.23027656
A26: 687b3076000000000d01bc26 | B26: normal | C26: 初中生书包怎么选？两款热门款选哪个？ | D26: 姐姐上了初中以后，书本越来越多，长期负重体态都不好了，所以这学期我决定给她换个护脊的初中生书包，把市面上比较火的两款护脊书包“戈撒驰”和“贝克曼”买回来做了对比，来说说我的感受吧！戈撒驰这款书包真的是“黑科技”满满！后背内侧隐藏了身高刻度，140-180cm可调，可以说是身高定制书包，也就是无论哪个年龄阶段都能精准适配的“高”定包。内置的U型铝制支撑杆，是高级登山包才有的设计️，不仅支撑力强，还能有效防止书包挤压脊柱。按照正确步骤背好后，通过肩带、背垫、腰垫分散书包压力，实现有效减负，效果可达64.8%！孩子背起来更轻松，腰背不自觉地就挺直了。容量是30+5L扩容款，主隔层塞12本课本+2本词典还有空隙，副隔层放练习册、作业本，有个前袋拉开能放足球、羽毛球拍这些比较大件的体育用品！很实用！侧兜弹力网面装运动水壶不掉，另一边放公交卡不怕丢。配套的笔袋我也买回来了，质量很好还很能装。贝克曼这款主打S型护脊铝支架，藏在背部，贴合脊椎曲线，背起来很稳，不会压到背。胸前调节扣灵活，拉紧后晃动减少，不过没有身高调节，它的减压效果是40%，姐姐试了下，同样的书本背起来虽然比普通书包轻，这款也是35L的大容量，有书本、文具、卡片的收纳区，不过孩子外出运动比如打羽毛球，就得单独用其他袋子装拍子了。笔袋的容量比较小，收纳空间有限。总结一下：两款都有护脊认证，戈撒驰的调节功能太适合青春期孩子，从初中用到高中没问题，35L 大容量+精准分区实用性拉满。贝克曼适合身高稳定的孩子，而且两个护脊书包都采用了环保面料，扎实耐用。最后姐姐还是选了戈撒驰，现在背书包都是挺直腰板，老母亲终于放心了！#Gotyasatch护脊书包[话题]# #戈撒驰护脊书包[话题]# #gotyasatch书包[话题]# #戈撒驰书包[话题]# #德国戈撒驰书包[话题]# #小学生书包[话题]# #护脊书包[话题]# #大容量书包[话题]# #护脊书包分享[话题]# #初中生书包[话题]# #高颜值书包[话题]# #书包分享[话题]# #戈撒驰高定护脊书包[话题]# #戈撒驰身高定制书包[话题]# | E26: =LEN(D26) -> 886 | F26: 219 | G26: 97 | H26: 19 | I26: 24 | J26: 359 | K26: 涵涵妈咪nemo | L26: 667a89a10000000007006f3b | M26: 广东 | N26: 2025-07-19 12:27:12 | O26: https://www.xiaohongshu.com/user/profile/667a89a10000000007006f3b?&xsec_source=pc_note | P26: https://www.xiaohongshu.com/discovery/item/687b3076000000000d01bc26?app_platform=android&ignoreEngage=true&app_version=8.47.0&share_from_user_hidden=true&xsec_source=app_share&type=normal&xsec_token=CBkhdRutn_6fgPa56eN7U1lSgNKnzPftHGnCtDVwGm5jI=&author_share=1 | Q26: Gotyasatch护脊书包,戈撒驰护脊书包,gotyasatch书包,戈撒驰书包,德国戈撒驰书包,小学生书包,护脊书包,大容量书包,护脊书包分享,初中生书包,高颜值书包,书包分享,戈撒驰高定护脊书包,戈撒驰身高定制书包 | R26: =VLOOKUP(A26,[1]蒲公英数据!A:H,8,0) -> 0.10703479 | S26: =VLOOKUP(A26,[1]蒲公英数据!A:I,9,0) -> 0.018915706 | T26: =VLOOKUP(A26,[1]蒲公英数据!A:J,10,0) -> 0.22678512
... A37: 6862613c000000002400c0c8 | B37: normal | C37: 喜提“高”定包：这护脊书包太 “哇噻” 了！ | D37: 作为营养师妈妈，我知道孩子成长的每个细节都不能马虎 尤其是即将五年级的滋滋，正值成长发育期 稍不注意就会导致体态、健康方面出现问题 而书包，是每天陪伴孩子的 “亲密伙伴” 也是身体负重的主要来源，千万不能忽视 我用 “研究食谱” 的劲儿做了超多功课 终于挖到了我俩都非常满意的戈撒驰护脊书包，必须来和大家唠唠- 开箱验货：细节控疯狂心动拆箱瞬间就被它的质感征服，花色我选的暗夜花语，很适合女孩子，实物好看又高级～PET环保面料摸起来厚实又顺滑，还能防水！选购的时候就看到它后背内侧有身高刻度，拿到手实际调过之后感觉这个设计很意外，因为它可以根据孩子身高调节到140cm-180cm的任何尺寸，根据身高定制的书包怎么不算是“高”定包呢就不用频繁给娃换书包啦- 硬核护脊：真材实料，科学有效 滋滋四年级的时候书包已经塞不下她的课本了，背着像是压在身上的大山，每天回家不是喊重就是喊累，所以我才选择了这款真的能够专业护脊，科学减负的护脊书包！内置的U型铝制支撑杆贴合后背，防止书包挤压脊柱，她背上也能挺直腰杆。而且按步骤正确背负后，可以把书包重量分散到腰背部，滋滋说“感觉书包像长在身上，不会晃来晃去”！加厚肩带像给肩膀敷了层 “云朵面膜”，背了半小时也没喊累，老母亲终于不用天天担心她驼背、脊柱侧弯了- 分区收纳：比我的食材分类盒还合理 作为一个爱分类收纳的营养师，看到这个书包的隔层设计直接狂喜！35L 大容量，主隔层能轻松塞下笔记本电脑；副隔层装课本、作业，还有他们家大容量的同款笔盒，我也买回来了；侧边口袋单手抽放水杯或者雨伞都超方便，再加上专门的多功能收纳袋，钥匙、钱包、纸巾这些物品归纳得很好，特别是女孩子的一些私密东西装这里特别好！滋滋自己整理书包时，还说“找东西快多了，不怕迟到啦”-戈撒驰的这款护脊书包不仅能保护孩子脊柱，不用我追着喊“别驼背”，细节设计上也处处贴心~无论家长们是想买小学生书包，还是初中生书包，都可以闭眼入#Gotyasatch护脊书包[话题]##戈撒驰护脊书包[话题]##gotyasatch书包[话题]##戈撒驰高定护脊书包[话题]# #戈撒驰书包[话题]##德国戈撒驰书包[话题]##小学生书包[话题]##护脊书包[话题]##护脊书包分享[话题]##初中生书包[话题]##大容量书包[话题]##高颜值书包[话题]##书包分享[话题]# | E37: =LEN(D37) -> 985 | F37: 543 | G37: 132 | H37: 49 | I37: 21 | J37: 745 | K37: 晚风不晚w | L37: 634acb7c000000001802e4f0 | M37: 江苏 | N37: 2025-06-30 11:11:22 | O37: https://www.xiaohongshu.com/user/profile/634acb7c000000001802e4f0?&xsec_source=pc_note | P37: https://www.xiaohongshu.com/discovery/item/6862613c000000002400c0c8?app_platform=android&ignoreEngage=true&app_version=8.47.0&share_from_user_hidden=true&xsec_source=app_share&type=video&xsec_token=CBepcPxEIB7gbBLY5im--WcLyvi6fbCiLBsOUa6Xx_8xY=&author_share=1 | Q37: Gotyasatch护脊书包,戈撒驰护脊书包,gotyasatch书包,戈撒驰高定护脊书包,戈撒驰书包,德国戈撒驰书包,小学生书包,护脊书包,护脊书包分享,初中生书包,大容量书包,高颜值书包,书包分享 | R37: =VLOOKUP(A37,[1]蒲公英数据!A:H,8,0) -> 0.16064369 | S37: =VLOOKUP(A37,[1]蒲公英数据!A:I,9,0) -> 0.024513893 | T37: =VLOOKUP(A37,[1]蒲公英数据!A:J,10,0) -> 0.18290807
A38: 686f2d9b0000000023007f39 | B38: normal | C38: Deepseek推了8次的千元护脊书包，值得冲吗 | D38: 最近为了给娃挑个护脊书包，我快把 AI 问吐了！从 ChatGPT 到Deepseek，输入 “千元护脊书包推荐”，8次搜索结果都首推戈撒驰。这到底是大数据玄学，还是真有两把刷子？！专门跑去线下店看过，书包和背部贴合得像1V1定制的一样。确实是心动的，不过毕竟千元价位，纠结症又犯了...这一波被DS按着头的安利，到底值不值得听？有没有买过的姐妹来说说：耐造程度咋样？求真实反馈！！！#护脊书包[话题]# #宝妈求助[话题]# #Deepseek[话题]# #Gotyasatch护脊书包[话题]# | E38: =LEN(D38) -> 249 | F38: 111 | G38: 68 | H38: 55 | I38: 34 | J38: 268 | P38: https://www.xiaohongshu.com/explore/686f2d9b0000000023007f39?xsec_token=MBmgL9GZA1UIy3NLUvDlO-zT04UBi_LtuFibV2Dj_72rg=&xsec_source=pc_pgy | R38: =VLOOKUP(A38,[1]蒲公英数据!A:H,8,0) -> 0.12955628 | S38: =VLOOKUP(A38,[1]蒲公英数据!A:I,9,0) -> 0.006885328 | T38: =VLOOKUP(A38,[1]蒲公英数据!A:J,10,0) -> 0.17954142
A39: 68818c11000000000b02fe08 | B39: normal | C39: 选护脊书包别盲目跟风，适配成长才是关键 | D39: 以前图好看，给娃买的都是卡通图案的书包，看着轻巧，其实背带又细又软，没什么支撑性。刚开始没在意，突然有一天发现娃写作业时总歪着肩膀，说脖子和肩膀酸，后来观察到娃走路都有点含胸驼背了！咨询了儿保专家才知道是肩膀长期承受重力导致的不仅肩颈疼，时间久了脊柱还可能变形，影响健康。所以选书包真不是看颜值就行，减负护脊很重要！今天一篇告诉你如何给孩子挑选到适合的护脊书包，可参考图2-3我给孩子选的是这款德国戈撒驰护脊书包！它后背隐藏的身高刻度，140-180cm可调节，娃今年148cm，轻轻移动到对应刻度即可；明年长高了再调一次，书包又能严丝合缝贴合后背。就像给每个阶段的孩子定制的专属书包，不管长多快，脊柱都能被准确托住，到时候直接给她当初中生书包用，这个可以针对身高进行定制的“高”定包太省妈了！内置的U型铝制支撑杆，符合人体工学，能有效吸收书包内部的压力，结合高弹背板形成支撑力，背起来不往下坠，脊柱就不会被拉扯到啦，再加上加宽加厚肩带、可调节胸扣和腰带，不仅能牢牢固定书包，还能将肩部重量均匀分散到腰背部，实现有效减负，真正做到专业护脊！35L扩容大容量，多层分区让收纳变得很简单！小学高年级课本增多，更需要这种大容量的书包！日常的书本、辅导书、作业、饭盒都能放，侧边还可以装水杯、雨伞、钥匙等，前袋一拉连足球都能装下。他家配套的笔袋我也给娃买了，尺子、笔、修正带全都能装下啦。书包材质不是那种软趴趴的，它采用的是德国PET环保面料，防水扎实又挺阔，质感+颜值均在线！家长们别再盲目跟风选不实用的书包，帮孩子挑个适合的护脊书包，守护孩子健康成长✌️#Gotyasatch护脊书包[话题]# #戈撒驰护脊书包[话题]# #gotyasatch书包[话题]# #戈撒驰书包[话题]# #德国戈撒驰书包[话题]# #小学生书包[话题]# #护脊书包[话题]# #大容量书包[话题]# #护脊书包分享[话题]# #初中生书包[话题]# #高颜值书包[话题]# #书包分享[话题]# #戈撒驰高定护脊书包[话题]# #戈撒驰身高定制书包[话题]# | E39: =LEN(D39) -> 869 | F39: 210 | G39: 91 | H39: 24 | I39: 52 | J39: 377 | K39: 糖糖糖 | L39: 5c1369926d4a730001d4470d | M39: 辽宁 | N39: 2025-07-24 09:42:24 | O39: https://www.xiaohongshu.com/user/profile/5c1369926d4a730001d4470d?&xsec_source=pc_note | P39: https://www.xiaohongshu.com/discovery/item/68818c11000000000b02fe08?app_platform=android&ignoreEngage=true&app_version=8.47.0&share_from_user_hidden=true&xsec_source=app_share&type=normal&xsec_token=CBbV21eOPrkAb9rj3f07H1P2zU-Fd49OInTx3evFp28v4=&author_share=1 | Q39: Gotyasatch护脊书包,戈撒驰护脊书包,gotyasatch书包,戈撒驰书包,德国戈撒驰书包,小学生书包,护脊书包,大容量书包,护脊书包分享,初中生书包,高颜值书包,书包分享,戈撒驰高定护脊书包,戈撒驰身高定制书包 | R39: =VLOOKUP(A39,[1]蒲公英数据!A:H,8,0) -> 0.10154154 | S39: =VLOOKUP(A39,[1]蒲公英数据!A:I,9,0) -> 0.0269798 | T39: =VLOOKUP(A39,[1]蒲公英数据!A:J,10,0) -> 0.17691221
A40: 68620552000000002400d8e4 | B40: normal | C40: 现在的初中生书包太逆天，还能跟着娃长高！ | D40: [种草R]我家初中娃为八下备考，书包塞得像小山⛰️每天回家喊肩膀酸，最近发现她走路弯腰驼背，脊柱都要被压弯了！娃的成绩重要，体态更不能毁啊！ 我做了大量功课，挖到德国戈撒驰护脊书包，今天开箱实测，拯救“小虾米”体态[向右R]护脊减负黑科技，堪称“脊柱保镖”先说这个书包我觉得很独特的一点，是它可以根据身高进行定制，在140cm-180cm根据孩子成长自由调节到合适的位置，孩子年年长个，不能调的书包半年就卡脖子，这款从初一用到高三也可以不用换。而且它内置的U型铝制支撑杆，据说是专业登山包同款配置，有德国IGR人体工学认证，贴合孩子的背部曲线，娃了用半个月，身姿都挺拔了。背书包时自觉挺直腰。这款初中生书包采用多点支撑承托，把集中在肩部的重量分散到腰部和背部。孩子直说，以前的书包背着肩膀像是快被勒断了，现在护脊书包背很久都不酸。[向右R]颜值实用兼备，初中生超爱[种草R]戈撒驰不愧是专业“研究”学生娃的，太懂他们的审美了！我给孩子选的是很清新的蓝色，还有他们家同款大容量笔盒，她拿到就爱不释手。35L扩容大容量，符合初中生的收纳需求：主+副隔层装书本、作业、笔盒，侧边袋可以放水杯和雨伞，平时喜欢的小挂件也可以挂在包上。扩容拉链一拉开空间更大了，运动会当装备包完全没问题。[向右R]面料扎实，背负舒适，防水更安心[种草R]背垫是高弹海绵的，中空凹槽+3D 眼蜂窝网面设计，夏天背后背也清爽，不会汗湿校服。加宽加厚的蝴蝶型肩带，不勒肩、不溜肩，背起来更舒服。整体采用的是PET环保面料，还防水，方方面面的细节都考虑到位了，真的很用心在设计。[向右R]之前也给孩子买过不少书包，但只有这款深入她心！每天都爱惜得很，看着娃现在每天放学回家不再喊累，腰背挺得直直的，我就知道这款护脊书包选对了！如果你也在给孩子选初中生书包，这篇一定要认真看~#Gotyasatch护脊书包[话题]# #戈撒驰护脊书包[话题]# #gotyasatch书包[话题]# #戈撒驰书包[话题]# #德国戈撒驰书包[话题]# #小学生书包[话题]# #护脊书包[话题]# #大容量书包[话题]# #护脊书包分享[话题]# #初中生书包[话题]# #高颜值书包[话题]# #书包分享[话题]# | E40: =LEN(D40) -> 931 | F40: 67 | G40: 21 | H40: 14 | I40: 10 | J40: 112 | K40: 大H家有初中生 | L40: 5a7dc2d94eacab1a95ee9bbc | M40: 湖北 | N40: 2025-06-30 10:03:27 | O40: https://www.xiaohongshu.com/user/profile/5a7dc2d94eacab1a95ee9bbc?&xsec_source=pc_note | P40: https://www.xiaohongshu.com/discovery/item/68620552000000002400d8e4?app_platform=android&ignoreEngage=true&app_version=8.47.0&share_from_user_hidden=true&xsec_source=app_share&type=normal&xsec_token=CBepcPxEIB7gbBLY5im--WcLbOMxP6CyHrBRWZtaoPW-k=&author_share=1 | Q40: Gotyasatch护脊书包,戈撒驰护脊书包,gotyasatch书包,戈撒驰书包,德国戈撒驰书包,小学生书包,护脊书包,大容量书包,护脊书包分享,初中生书包,高颜值书包,书包分享 | R40: =VLOOKUP(A40,[1]蒲公英数据!A:H,8,0) -> 0.1044487 | S40: =VLOOKUP(A40,[1]蒲公英数据!A:I,9,0) -> 0.0047086035 | T40: =VLOOKUP(A40,[1]蒲公英数据!A:J,10,0) -> 0.17158822
A41: 6895a25a000000002301a455 | B41: normal | C41: 美国VS中国！为啥回国后要给娃换护脊书包 | D41: 我家弟弟从美国回国读公立，变化特别大，尤其明显的就是书包美国小学生的书包≈空书包课本NO放学校作业NO 基本没有水壶NO 喝直饮水偶尔一个文件夹，大部分都是空的中国小学生的书包=20斤重必带：备用红领巾、小黄帽、文具、水壶书：语文书、数学书、英语书、科学书、道法、书法、美术、音乐本子：回家作业本、语文课堂作业本、数学口算本、科学重点笔记….作文本、方格本，多到数不清只带上课的书都超重，每周还要带一次书法工具箱和乒乓球拍♥️回了国才知道为啥大家都要给孩子买减负的护脊书包，普通书包光是背上腰背就被压弯了，更别提走路，长期这样很容易影响脊柱健康。新学期我们马上升五年级啦，书包预计会更重，暑假给孩子准备学习用品的时候，我了解了些护脊的知识分享给大家（图4），同时新入手了戈撒驰护脊书包也必须安利给大家：1️⃣带身高刻度，是可以根据孩子身高定制的书包。140-180cm可调节，身高在这个区间都可以背，弟弟正是长个子的时候，它能精准适配孩子成长，小升初能继续当初中生书包用，省钱又省心2️⃣内置的U型铝制支撑杆太懂孩子！完美贴合脊柱曲线，结合背板巧妙阻挡压力，不会挤压脊椎，背起来很舒服～加上胸带+ 腰带+肩带的多重承托设计，简直是物理减负大师，轻轻松松就能挺直腰杆，不用担心负重影响体态啦！3️⃣30L 大容量！书本、红领巾、小黄帽还有他家配套大容量笔盒分层放得整整齐齐，侧边放雨伞水杯，娃在操场疯跑都晃不掉，再也没丢过水杯啦，收纳力MAX～4️⃣耐造又安全，细节控妈妈直接冲！面料摸上去很有质感，下雨天溅到水擦一擦就好，背几年都跟新的一样～包身反光条设计，夜晚接娃老远就能看见那抹亮色，安全感满满。给弟弟换了这个护脊书包后，他再也没抱怨肩带勒得肩膀疼，走路挺拔多了，而且每天自己整理收纳学习资料，看来已经适应国内的节奏啦，老母亲也能松一口气了！#Gotyasatch护脊书包[话题]# #戈撒驰护脊书包[话题]# #gotyasatch书包[话题]# #戈撒驰身高定制书包[话题]# #戈撒驰书包[话题]# #德国戈撒驰书包[话题]# #戈撒驰高定护脊书包[话题]# #小学生书包[话题]# #护脊书包[话题]# #大容量书包[话题]# #护脊书包分享[话题]# #初中生书包[话题]# #高颜值书包[话题]# #书包分享[话题]# | E41: =LEN(D41) -> 967 | F41: 124 | G41: 82 | H41: 19 | I41: 13 | J41: 238 | K41: 米米和点点在美国 | L41: 606585b1000000000101c9de | M41: 浙江 | N41: 2025-08-08 12:47:51 | O41: https://www.xiaohongshu.com/user/profile/606585b1000000000101c9de?&xsec_source=pc_note | P41: https://www.xiaohongshu.com/discovery/item/6895a25a000000002301a455?app_platform=android&ignoreEngage=true&app_version=8.47.0&share_from_user_hidden=true&xsec_source=app_share&type=normal&xsec_token=CBnjRxmTkdR3m3KskfN9ZuNYS-nWjFn3gTpyAhdG3NjAU=&author_share=1 | Q41: Gotyasatch护脊书包,戈撒驰护脊书包,gotyasatch书包,戈撒驰身高定制书包,戈撒驰书包,德国戈撒驰书包,戈撒驰高定护脊书包,小学生书包,护脊书包,大容量书包,护脊书包分享,初中生书包,高颜值书包,书包分享 | R41: =VLOOKUP(A41,[1]蒲公英数据!A:H,8,0) -> 0.063265868 | S41: =VLOOKUP(A41,[1]蒲公英数据!A:I,9,0) -> 0.26115343 | T41: =VLOOKUP(A41,[1]蒲公英数据!A:J,10,0) -> 0.16405308
A42: 68885195000000002400bdd6 | B42: normal | C42: 四年级娃的升学礼物：好看的护脊书包安排上 | D42: 家有准四年级娃的妈妈们看过来！班主任提醒得太对了，高年级挑书包真得选减负护脊的。这不，新课本一整理，旧书包直接被塞到变形，拎在手上重量非常明显，孩子背着走路歪歪扭扭，当妈的真怕影响脊柱发育！我紧急做功课换了戈撒驰护脊书包，用过直接想安利给所有家长为啥选护脊书包？四年级课程变多，书本、学习用品一装，普通书包没支撑，孩子背久了脊柱压力大，容易弯腰驼背。选对护脊书包，既是给身体减负，也是给学习“助力”，毕竟舒舒服服地才能好好学嘛～✨ 为啥选戈撒驰，这几点疯狂心动！1️⃣适配成长的可调节设计，四年级用到初中都ok！内侧藏着身高刻度尺，140-180cm身高区间自由调，孩子自己都可以操作。她现在正是身高猛长期，一个能随身高定制的护脊书包可以解决大问题2️⃣硬核结构，真护脊不空谈！内置U型铝制支撑杆，符合人体工学，贴合孩子脊柱曲线，结合高弹背板一起给脊柱稳稳支撑。搭配可卸力的胸扣、肩扣、腰带，背好后重量从肩膀分散到腰背，走路不晃、不驼背，背再久也不累，老母亲终于不用天天念叨“别弯腰”啦～3️⃣科学分区收纳，四年级杂乱物品秒归位！30L大容量，隔层、侧袋分工明确，书本、作业、练习册、水杯、雨伞各就各位，再也不用像之前“掏盲盒”那样找东西，女儿现在收拾书包超利索，等上初中扩容拉链打开瞬间多出5L空间，再多书也装得下！还有个前袋，塞校服、足球妥妥的，实用性拉满！他们家配套的大容量笔盒我也买回来了加分项：安全与耐用双在线！- 360度反光条：晚上校门口接娃，老远就能看见，安全感爆棚-不是需要小心呵护的面料，日常小剐蹭一点都不用担心，基本不会留下划痕，爱打闹的四年级孩子也不怕造女儿拿到书包第一句就是“配色好漂亮”，背了几天肩膀也没有出现酸疼感，老母亲真心觉得值！正在考虑给娃换书包的家长，闭眼冲戈撒驰护脊书包，护脊又省心，让升学路上少份焦虑#Gotyasatch护脊书包[话题]# #戈撒驰护脊书包[话题]# #戈撒驰身高定制书包[话题]# #gotyasatch书包[话题]# #德国戈撒驰书包[话题]# #护脊书包[话题]# #护脊书包分享[话题]# #初中生书包[话题]# #高颜值书包[话题]# #戈撒驰高定护脊书包[话题]# | E42: =LEN(D42) -> 919 | F42: 154 | G42: 59 | H42: 13 | I42: 11 | J42: 237 | K42: 古德的七七 | L42: 5bcf497e06f9880001a4e1c9 | M42: 甘肃 | N42: 2025-07-29 06:21:32 | O42: https://www.xiaohongshu.com/user/profile/5bcf497e06f9880001a4e1c9?&xsec_source=pc_note | P42: https://www.xiaohongshu.com/discovery/item/68885195000000002400bdd6?app_platform=android&ignoreEngage=true&app_version=8.47.0&share_from_user_hidden=true&xsec_source=app_share&type=normal&xsec_token=CBtaPkwJ0ri0aNzuGoBEzszKk5wXtLyOA82fHH-dZuw2k=&author_share=1 | Q42: Gotyasatch护脊书包,戈撒驰护脊书包,戈撒驰身高定制书包,gotyasatch书包,德国戈撒驰书包,护脊书包,护脊书包分享,初中生书包,高颜值书包,戈撒驰高定护脊书包 | R42: =VLOOKUP(A42,[1]蒲公英数据!A:H,8,0) -> 0.11500418 | S42: =VLOOKUP(A42,[1]蒲公英数据!A:I,9,0) -> 0.13688674 | T42: =VLOOKUP(A42,[1]蒲公英数据!A:J,10,0) -> 0.14594128
A43: 688856990000000003032028 | B43: normal | C43: 6年教师+经验宝妈教你这样选护脊书包! | D43: 以前当老师的时候，见过太多孩子因书包太重含胸驼背的样子，现在自己成了妈妈，看着女儿瘦瘦小小的身板，背着沉甸甸的书包，我比谁都清楚：孩子的脊柱就像春天的嫩芽，可经不起这样长期拉扯。而且孩子学业一年比一年重，所以趁着暑假，我计划给她换个真正能减负的护脊书包，攻略做得比我当年备教案还认真，对比了十几款，最终敲定了戈撒驰护脊书包。我完全是用教育工作者+妈妈的双重标准在把关：首先是成长适配性，这是我最看重的。女儿现在142cm，正是蹿个子的时候，这款书包可以按身高定制，内侧的身高刻度尺从140-180cm随意调，也算是名副其实的“高”定包了~刚收到她就自己照着身高调到适合的位置，背起来后背贴得紧紧的，不像以前的书包背着总晃悠，感觉等上初中了还可以当初中生书包用。然后是科学减负，这是护脊书包的核心：戈撒驰内置U型铝制支撑杆，可以吸收书包撞击背部的压力，有效保护孩子脊柱，再加上四点承托设计，让肩、胸、腰一起受力，加宽加厚的肩带、高弹背垫和加厚腰垫，能把肩部重量分散到腰背部，就算娃背了很多东西，整个人也能站得笔直，连坐姿都不自觉挺拔了。此外，这款书包的细节设计也很贴心：娃书包背久了怕勒怕闷，但这款书包背垫是Y字形蜂窝网面和中空凹槽设计，便于散热透气，夏天背再久也不闷汗；30L大容量分层清晰，有2个主隔层和1个多功能收纳仓：课本、练习本、钥匙、水杯各有位置，配套的笔袋容量也很大，现在她收拾笔袋和书包都不用我操心了。最惊喜的是反光设计，傍晚接她放学，老远就能看见书包上的光，安全感满满。以前总提醒学生“背挺直”，现在才明白：比起口头叮嘱，使用一个能真正减负的护脊书包，才是给孩子最好的体态引导。毕竟，比起成绩单上的数字，我更希望她能抬头挺胸地走过整个学生时代呀～#Gotyasatch护脊书包[话题]# #戈撒驰护脊书包[话题]# #gotyasatch书包[话题]# #戈撒驰书包[话题]# #德国戈撒驰书包[话题]# #小学生书包[话题]# #护脊书包[话题]##大容量书包[话题]# #护脊书包分享[话题]# #初中生书包[话题]# #高颜值书包[话题]# #书包分享[话题]# #戈撒驰高定护脊书包[话题]# #戈撒驰身高定制书包[话题]# | E43: =LEN(D43) -> 924 | F43: 158 | G43: 85 | H43: 19 | I43: 5 | J43: 267 | K43: 超大只的妮妮 | L43: 5f4c5b07000000000101f165 | M43: 安徽 | N43: 2025-07-29 12:03:41 | O43: https://www.xiaohongshu.com/user/profile/5f4c5b07000000000101f165?&xsec_source=pc_note | P43: https://www.xiaohongshu.com/discovery/item/688856990000000003032028?app_platform=android&ignoreEngage=true&app_version=8.47.0&share_from_user_hidden=true&xsec_source=app_share&type=normal&xsec_token=CBtaPkwJ0ri0aNzuGoBEzszNXccTDnT_ntxWqDGzusFEU=&author_share=1 | Q43: Gotyasatch护脊书包,戈撒驰护脊书包,gotyasatch书包,戈撒驰书包,德国戈撒驰书包,小学生书包,护脊书包,大容量书包,护脊书包分享,初中生书包,高颜值书包,书包分享,戈撒驰高定护脊书包,戈撒驰身高定制书包 | R43: =VLOOKUP(A43,[1]蒲公英数据!A:H,8,0) -> 0.096982903 | S43: =VLOOKUP(A43,[1]蒲公英数据!A:I,9,0) -> 0.094020048 | T43: =VLOOKUP(A43,[1]蒲公英数据!A:J,10,0) -> 0.14285714
A44: 685e8d3b000000001c031573 | B44: normal | C44: 儿子想要一个千元书包，该不该满足他？ | D44: 今年下半年孩子马上要上国际学校了，给他选书包这件事烦了我好几天，去学校办手续的时候发现很多孩子们背的书包都很特别，比较硬挺也很有支撑，问了一个孩子的妈妈说他家孩子背的是戈撒驰书包，可以护脊减轻孩子负担，但有点贵，我在想一个书包而已，真的有必要买这么贵的吗？普通书包难道不能满足日常使用需求？还有如果要买这类功能性书包的话，选购的时候要注意些什么？#初中生[话题]##育儿日常[话题]##名牌[话题]##书包[话题]##戈撒驰护脊书包[话题]##Gotyasatch护脊书包[话题]# | E44: =LEN(D44) -> 241 | F44: 169 | G44: 76 | H44: 62 | I44: 2 | J44: 309 | K44: 西西爱吃肉 | L44: 6777a4460000000015005117 | M44: 辽宁 | N44: 2025-06-27 12:52:38 | O44: https://www.xiaohongshu.com/user/profile/6777a4460000000015005117?&xsec_source=pc_note | P44: https://www.xiaohongshu.com/discovery/item/685e8d3b000000001c031573?app_platform=android&ignoreEngage=true&app_version=8.47.0&share_from_user_hidden=true&xsec_source=app_share&type=normal&xsec_token=CBKUO1y0avExSuAP2cnzQwni6gXf05rbym6MQMEJjqOOg=&author_share=1 | Q44: 初中生,育儿日常,名牌,书包,戈撒驰护脊书包,Gotyasatch护脊书包 | R44: =VLOOKUP(A44,[1]蒲公英数据!A:H,8,0) -> 0.122177 | S44: =VLOOKUP(A44,[1]蒲公英数据!A:I,9,0) -> 0.019748535 | T44: =VLOOKUP(A44,[1]蒲公英数据!A:J,10,0) -> 0.13443198
A45: 687f000800000000130122e7 | B45: normal | C45: 后悔买晚了！原来护脊书包真的能撑腰 | D45: 有次送十岁儿子上学，看着他背着书包前倾的背影，心里咯噔一下。作为一名育婴师，我太清楚脊柱健康对孩子的重要性了——这些年接触过不少小朋友，了解到脊柱侧弯已经成了儿童健康的第三大杀手，很多是从小书包没选对埋下隐患，跑跳时书包晃得像个钟摆，后背无支撑，久而久之孩子自然就养成含胸驼背的坏习惯。所以换护脊书包这事，我一点不敢含糊，对比了十几款，最终敲定了戈撒驰——不是跟风，是它的专业设计真的戳中了我。​首先让我心动的是它内侧隐藏的身高刻度尺，140-180cm随意调节，匹配不同阶段孩子的成长需求。我儿子现在十岁，正是蹿个子的时候，书包能跟着他“同步升级”，根据身高定制，就像是“高”定包，即使上初中也不用特意换初中生书包啦内置的U型铝制支撑杆，符合人体工学，像给脊柱加了隐形防护网，这才是护脊书包该有的硬核配置。之前看到大家有个误区：书包轻就能减负。其实不然，减负看的是支撑力和承托力。这款书包背上后，​加宽加厚的肩带、高弹的背垫以及加厚的腰垫，牢牢包裹住孩子身体，形成多点承托系统，抗震减压，而且经专业实测减负效果达64.8%。以前儿子放学回家总说肩膀酸，现在背戈撒驰走一路，放下书包还能蹦蹦跳跳去打球，一点不累的样子。护脊书包的收纳也很讲究，比如这个书包分区合理，作业、书本、练习册以及水杯、雨伞、钥匙都能对应放置，扩容拉链打开瞬间多出5L空间，配套的笔袋也跟书包一样，特能装！还有个创意前袋，打开能放足球、衣服这种大件物品。面料摸上去质感很好，昨天我看儿子写作业写不出来烦躁的用笔在书包上划拉，正想说他呢，一看书包没啥事儿，也就随他了，心情不好时适当发泄下也是应该的而且这个面料还是环保的，感觉比较安全。脊柱发育是单行道，选对护脊书包，从小让孩子保持良好的体态，比什么都重要。​#Gotyasatch护脊书包[话题]# #戈撒驰护脊书包[话题]# #gotyasatch书包[话题]# #戈撒驰书包[话题]# #德国戈撒驰书包[话题]# #小学生书包[话题]# #护脊书包[话题]# #大容量书包[话题]# #护脊书包分享[话题]# #初中生书包[话题]# #高颜值书包[话题]# #书包分享[话题]# #戈撒驰高定护脊书包[话题]# #戈撒驰身高定制书包[话题]# | E45: =LEN(D45) -> 934 | F45: 141 | G45: 105 | H45: 22 | I45: 8 | J45: 276 | K45: 汪小妮的90后辣妈 | L45: 6401a76c000000002a00ae31 | M45: 浙江 | N45: 2025-07-22 11:51:06 | O45: https://www.xiaohongshu.com/user/profile/6401a76c000000002a00ae31?&xsec_source=pc_note | P45: https://www.xiaohongshu.com/discovery/item/687f000800000000130122e7?app_platform=android&ignoreEngage=true&app_version=8.47.0&share_from_user_hidden=true&xsec_source=app_share&type=video&xsec_token=CBcmwSdrBEFQSlPQtE-mrJX0dKjC3IcqGBA0Lg82aY0vU=&author_share=1 | Q45: Gotyasatch护脊书包,戈撒驰护脊书包,gotyasatch书包,戈撒驰书包,德国戈撒驰书包,小学生书包,护脊书包,大容量书包,护脊书包分享,初中生书包,高颜值书包,书包分享,戈撒驰高定护脊书包,戈撒驰身高定制书包 | R45: =VLOOKUP(A45,[1]蒲公英数据!A:H,8,0) -> 0.18441798 | S45: =VLOOKUP(A45,[1]蒲公英数据!A:I,9,0) -> 0.04399376 | T45: =VLOOKUP(A45,[1]蒲公英数据!A:J,10,0) -> 0.12943495
A46: 685cdcac000000000d0274cc | B46: normal | C46: 不是所有书包都护脊！一篇教你选对护脊书包 | D46: 作为一个小学4年给娃换过6个书包的常年踩坑老母亲，我悟了：普通书包再好看，背久了驼背+肩膀酸，舞蹈课练出的挺拔体态全白费！尤其我家156cm的“舞蹈小孩姐”马上进入五年级，课程增加书包重量飙升，再继续背那些普通书包，造成脊柱侧弯可就后悔了！所以趁娃升学前赶紧做功课，入手了德国戈撒驰护脊书包，孩子爸都夸我太会选了，今天就给大家分享下~护脊书包选购3大铁律1⃣️别被“轻”忽悠！支撑力才是核心❌ 超轻书包装书后肩带勒肉，负重感还会增加，娃走路直往后仰✅ 科学减负=分散压力！戈撒驰这款书包内置的U型铝制支撑杆，和专业户外登山包同款设计，孩子背上后我用手试探过，和孩子背部是真贴合，几乎感觉不到书包对背部的压迫感，再加上背板能够提供良好的支撑性，装满书后底部都没有以前那种往下坠的感觉了。上身测试时把上肩扣、胸扣、腰扣扣好，娃说像背了个“隐形气球”，重量被“隐形气球”拉起来，腰背自然就挺直了，舞蹈生再也不怕被书包毁了好体态！2⃣️身高适配≠将就！必须“动态成长”❌ 普通书包用半年就嫌小，肩带调最长还吊在屁股上✅刚拿到这款护脊书包我就迫不及待先打开了它内侧隐藏的身高刻度，从140-180cm，背到初中完全没有问题（又省一个初中生书包），对于家里有个“疯狂长个儿“的娃的家庭来说，这点真的很惊喜，而且PET环保面料扎实耐用又防水，终于不用频繁换书包了！3⃣️大容量≠胡乱塞！分区收纳才合理❌ 书包没分区？书本乱堆重心不稳，脊椎天天被拉扯！✅ 护脊书包必须科学分层！主隔层放课本、作业、笔盒，副隔层可装笔记本，中间的扩容空间，拉开30L秒变35L。侧兜插水杯、雨伞，还有一个前袋放舞蹈鞋和舞蹈服。他们家同款的大容量笔盒我也买回来了，两者搭配，收纳王者没跑了！最后说句大实话护脊书包不是常买常新，尤其是在一年窜高10cm的年龄，可调节的人性化设计才是动态适应成长的有效方式～#Gotyasatch护脊书包[话题]# #戈撒驰护脊书包[话题]# #gotyasatch书包[话题]# #戈撒驰书包[话题]# #德国戈撒驰书包[话题]# #小学生书包[话题]# #护脊书包[话题]# #大容量书包[话题]# #护脊书包分享[话题]# #初中生书包[话题]# #大容量书包[话题]# #高颜值书包[话题]# #书包分享[话题]# | E46: =LEN(D46) -> 958 | F46: 164 | G46: 76 | H46: 18 | I46: 15 | J46: 273 | K46: 兰姐Lance | L46: 55691c49e58d130c65c1886b | M46: 上海 | N46: 2025-06-26 06:07:10 | O46: https://www.xiaohongshu.com/user/profile/55691c49e58d130c65c1886b?&xsec_source=pc_note | P46: https://www.xiaohongshu.com/discovery/item/685cdcac000000000d0274cc?app_platform=android&ignoreEngage=true&app_version=8.47.0&share_from_user_hidden=true&xsec_source=app_share&type=normal&xsec_token=CBeXm1ndMbVGlIlBTZxxcZKFeoByi8bl3Cp0HNlBoaKHo=&author_share=1 | Q46: Gotyasatch护脊书包,戈撒驰护脊书包,gotyasatch书包,戈撒驰书包,德国戈撒驰书包,小学生书包,护脊书包,大容量书包,护脊书包分享,初中生书包,高颜值书包,书包分享 | R46: =VLOOKUP(A46,[1]蒲公英数据!A:H,8,0) -> 0.10337559 | S46: =VLOOKUP(A46,[1]蒲公英数据!A:I,9,0) -> 0.0097100846 | T46: =VLOOKUP(A46,[1]蒲公英数据!A:J,10,0) -> 0.12795013
